Workbook
Name Loans: Summary!$J$20:$O$20

Sheet Model
B1: Sheets | C1: Sheet Type | D1: Description | E1: Links
B2: Model | C2: Assumptions | D2: Description of Sheets | E2: =HYPERLINK("#"&B2&"!A2",B2) -> Model
B3: List | C3: Assumptions | D3: Lists and model assumptions | E3: =HYPERLINK("#"&B3&"!A2",B3) -> List
B4: Data | C4: Input Sheet | D4: Actual lead metrics by region | E4: =HYPERLINK("#"&B4&"!A2",B4) -> Data
B5: Plan | C5: Input Sheet | D5: Plan lead metrics by region | E5: =HYPERLINK("#"&B5&"!A2",B5) -> Plan
B6: Cust | C6: Input Sheet | D6: Customer data (small data set) | E6: =HYPERLINK("#"&B6&"!A2",B6) -> Cust
B7: Hires | C7: Input Sheet | D7: Hires and terminations | E7: =HYPERLINK("#"&B7&"!A2",B7) -> Hires
B8: Sick | C8: Input Sheet | D8: Average sick days per employee | E8: =HYPERLINK("#"&B8&"!A2",B8) -> Sick
B9: FTE | C9: Input Sheet | D9: Full time equivalent workers | E9: =HYPERLINK("#"&B9&"!A2",B9) -> FTE
B10: General | C10: Input Sheet | D10: General financial metrics | E10: =HYPERLINK("#"&B10&"!A2",B10) -> General
B11: Other | C11: Input Sheet | D11: Other financial and ops metrics | E11: =HYPERLINK("#"&B11&"!A2",B11) -> Other
B12: Calcs | C12: Calculations sheet | D12: Primary calculations page | E12: =HYPERLINK("#"&B12&"!A2",B12) -> Calcs
B13: Check | C13: Error trapping | D13: Checks and balances for the model | E13: =HYPERLINK("#"&B13&"!A2",B13) -> Check
B14: Summary | C14: Output Sheet | D14: Primary output page | E14: =HYPERLINK("#"&B14&"!A2",B14) -> Summary

Sheet Lists
A1: Metric | B1: Measures | D1: Hires | E1: Years | F1: Regions | H1: Checks
A2: Linked Cell Spinner | B2: =Summary!B5 -> 3 | D2: FY 10 | E2: FY 12 | F2: England | H2: Model OK
A3: Linked Cell Listbox | B3: Core Deposits | D3: FY 11 | E3: FY 13 | F3: Scotland | H3: Check Model
A4: Region Cell Link | B4: 2 | D4: FY 12 | E4: FY 14 | F4: Wales
A5: Region | B5: =OFFSET(F1,B4,0,1,1) -> Scotland | D5: FY 13 | E5: FY 15 | F5: Northern Ireland
D6: FY 14 | E6: FY 16
D7: FY 15 | E7: FY 17
D8: FY 16 | E8: FY 18
D9: FY 17 | E9: FY 19
D10: FY 18 | E10: FY 20
D11: FY 19
D12: FY 20

Sheet Data
A1: Region | B1: Activity | C1: =OFFSET(Lists!$E$1,COLUMN()-2,0,1,1) -> FY 12 | D1: =OFFSET(Lists!$E$1,COLUMN()-2,0,1,1) -> FY 13 | E1: =OFFSET(Lists!$E$1,COLUMN()-2,0,1,1) -> FY 14 | F1: =OFFSET(Lists!$E$1,COLUMN()-2,0,1,1) -> FY 15 | G1: =OFFSET(Lists!$E$1,COLUMN()-2,0,1,1) -> FY 16 | H1: =OFFSET(Lists!$E$1,COLUMN()-2,0,1,1) -> FY 17 | I1: =OFFSET(Lists!$E$1,COLUMN()-2,0,1,1) -> FY 18 | J1: =OFFSET(Lists!$E$1,COLUMN()-2,0,1,1) -> FY 19 | K1: =OFFSET(Lists!$E$1,COLUMN()-2,0,1,1) -> FY 20
A2: England | B2: Net Income | C2: 7400 | D2: 8100 | E2: 8300 | F2: 9600 | G2: 10200 | H2: 10000 | I2: 10200 | J2: 10600 | K2: 10300
A3: England | B3: Revenue | C3: 28900 | D3: 33569 | E3: 34511 | F3: 35678 | G3: 38976 | H3: 40014 | I3: 41017.5 | J3: 42521.875 | K3: 48152.344
A4: England | B4: Diluted Earnings Per Share | C4: 3.1 | D4: 3.2 | E4: 3.35 | F4: 3.4 | G4: 3.45 | H4: 3.6 | I4: 4.5 | J4: 5.625 | K4: 7.03125
A5: England | B5: Dividends Per Share | C5: 0.97 | D5: 1.05 | E5: 1.11 | F5: 1.2 | G5: 1.23 | H5: 1.28 | I5: 1.6 | J5: 2 | K5: 2.5
A6: England | B6: Return on Assets | C6: 2.6 | D6: 2.4 | E6: 2.6 | F6: 2.5 | G6: 2.5 | H6: 2.6 | I6: 3.25 | J6: 4.0625 | K6: 5.078125
A7: England | B7: Return on Equity | C7: 23.4 | D7: 22.7 | E7: 26.8 | F7: 25.7 | G7: 27.6 | H7: 28.6 | I7: 30.75 | J7: 25.6875 | K7: 22.859375
A8: England | B8: Net Interest Margin | C8: 7.5 | D8: 7.8 | E8: 8.3 | F8: 8.3 | G8: 8.4 | H8: 8.7 | I8: 8.875 | J8: 9 | K8: 8.7
A9: England | B9: Efficiency Ratio | C9: 0.84 | D9: 0.9 | E9: 0.85 | F9: 0.87 | G9: 0.84 | H9: 0.88 | I9: 1.1 | J9: 1.375 | K9: 1.71875
A10: England | B10: Assets | C10: 440000 | D10: 465000 | E10: 480000 | F10: 520000 | G10: 550000 | H10: 620000 | I10: 675000 | J10: 698750 | K10: 668750
A11: England | B11: Loans | C11: 255923 | D11: 267900 | E11: 278900 | F11: 298765 | G11: 312900 | H11: 320984 | I11: 301230 | J11: 298765 | K11: 326921.88
A12: England | B12: Core Deposits | C12: 253651 | D12: 262890 | E12: 268931 | F12: 274900 | G12: 289150 | H12: 305918 | I12: 315918 | J12: 307123 | K12: 335918
A13: England | B13: Stockholder's Equity | C13: 28750 | D13: 30800 | E13: 31540 | F13: 32700 | G13: 33870 | H13: 34900 | I13: 35900 | J13: 36900 | K13: 37900
... A21: Scotland | B21: Diluted Earnings Per Share | C21: 2.1 | D21: 2.2 | E21: 2.35 | F21: 2.4 | G21: 2.45 | H21: 3.2 | I21: 4.5 | J21: 5.625 | K21: 3.6
A22: Scotland | B22: Dividends Per Share | C22: 0.67 | D22: =C22+0.1 -> 0.77 | E22: =D22+0.1 -> 0.87 | F22: =E22+0.1 -> 0.97 | G22: 0.67 | H22: =G22+0.1 -> 0.77 | I22: =H22+0.1 -> 0.87 | J22: =I22+0.1 -> 0.97 | K22: =J22+0.1 -> 1.07
A23: Scotland | B23: Return on Assets | C23: 1.6 | D23: =C23+0.1 -> 1.7 | E23: 1.6 | F23: 1.5 | G23: 3.5 | H23: 3.6 | I23: 4.25 | J23: 5.0625 | K23: 6.078125
A24: Scotland | B24: Return on Equity | C24: 22.4 | D24: =C24+0.1 -> 22.5 | E24: 25.8 | F24: 24.7 | G24: 28.6 | H24: 29.6 | I24: 31.75 | J24: 26.6875 | K24: 23.859375
A25: Scotland | B25: Net Interest Margin | C25: 6.5 | D25: =C25+0.1 -> 6.6 | E25: 7.3 | F25: 7.3 | G25: 9.4 | H25: 9.7 | I25: 9.875 | J25: 10 | K25: 9.7
A26: Scotland | B26: Efficiency Ratio | C26: 1.64 | D26: 1.74 | E26: 1.84 | F26: 1.94 | G26: 1.874 | H26: 1.88 | I26: 2.1 | J26: 2.375 | K26: 2.21875
A27: Scotland | B27: Assets | C27: 270000 | D27: =C27+0.1 -> 270000.1 | E27: 240000 | F27: 200000 | G27: 295000 | H27: 340000 | I27: 387500 | J27: 484375 | K27: 605468.75
A28: Scotland | B28: Loans | C28: 157961.5 | D28: =C28+0.1 -> 157961.6 | E28: 129450 | F28: 169382.5 | G28: 176450 | H28: 160492 | I28: 200615 | J28: 250768.75 | K28: 313460.94
A29: Scotland | B29: Core Deposits | C29: 146825.5 | D29: =C29+0.1 -> 146825.6 | E29: 154465.5 | F29: 137450 | G29: 164575 | H29: 152959 | I29: 147959 | J29: 153561.5 | K29: 147959
A30: Scotland | B30: Stockholder's Equity | C30: 14375 | D30: =C30+0.1 -> 14375.1 | E30: 15770 | F30: 16350 | G30: 16935 | H30: 17450 | I30: 17950 | J30: 18450 | K30: 18950
A31: Scotland | B31: Non-Performing Loans / Total Loans | C31: 0.7 | D31: =C31+0.1 -> 0.8 | E31: 0.5 | F31: 0.4 | G31: 2.2 | H31: 2.3 | I31: 2.7 | J31: 2.5 | K31: 2.3
A32: Scotland | B32: Allowance / Total Loans | C32: 1.9 | D32: =C32+0.1 -> 2 | E32: 2 | F32: 2 | G32: 4.1 | H32: 4.2 | I32: 3.9 | J32: 3.9 | K32: 4
A33: Scotland | B33: Allowance / Non-Performing Loans | C33: 2.45 | D33: =C33+0.1 -> 2.55 | E33: 2.55 | F33: 2.65 | G33: 4.7 | H33: 4.9 | I33: 4.9 | J33: 4.6 | K33: 4.9
A34: Scotland | B34: Net Charge Offs / Average Total Loans | C34: 0.7 | D34: =C34+0.1 -> 0.8 | E34: 0.6 | F34: 0.6 | G34: 2.5 | H34: 2.4 | I34: 2.3 | J34: 2.6 | K34: 2.5
A36: Wales | B36: Net Income | C36: 8140 | D36: 8910 | E36: 9130 | F36: 16560 | G36: 11220 | H36: 12100 | I36: 12320 | J36: 12760 | K36: 13530
A37: Wales | B37: Revenue | C37: 31790 | D37: 36925.9 | E37: 37962.1 | F37: 39245.8 | G37: 42873.6 | H37: 55015.4 | I37: 55019.25 | J37: 61774.062 | K37: 85967.578
A38: Wales | B38: Diluted Earnings Per Share | C38: 4.1 | D38: 4.2 | E38: 4.35 | F38: 4.4 | G38: 4.45 | H38: 4.6 | I38: 5.5 | J38: 6.625 | K38: 8.03125
A39: Wales | B39: Dividends Per Share | C39: 1.97 | D39: 2.05 | E39: 2.18 | F39: 2.5 | G39: 2.23 | H39: 2.28 | I39: 2.6 | J39: 3 | K39: 3.5
A40: Wales | B40: Return on Assets | C40: 3.6 | D40: 3.4 | E40: 3.6 | F40: 3.5 | G40: 3.5 | H40: 3.6 | I40: 4.25 | J40: 5.0625 | K40: 6.078125
A41: Wales | B41: Return on Equity | C41: 24.4 | D41: 23.7 | E41: 27.8 | F41: 26.7 | G41: 28.6 | H41: 29.6 | I41: 31.75 | J41: 26.6875 | K41: 23.859375
A42: Wales | B42: Net Interest Margin | C42: 8.5 | D42: 8.8 | E42: 9.3 | F42: 9.3 | G42: 9.4 | H42: 9.7 | I42: 9.875 | J42: 10 | K42: 9.7
A43: Wales | B43: Efficiency Ratio | C43: 1.84 | D43: 1.9 | E43: 1.85 | F43: 1.87 | G43: 1.84 | H43: 1.88 | I43: 2.1 | J43: 2.375 | K43: 2.71875
A44: Wales | B44: Assets | C44: 396000 | D44: 418500 | E44: 432000 | F44: 468000 | G44: 495000 | H44: 558000 | I44: 697500 | J44: 871875 | K44: 1089843.8
A45: Wales | B45: Loans | C45: 230330.7 | D45: 241110 | E45: 251010 | F45: 251010 | G45: 251010 | H45: 288885.6 | I45: 361107 | J45: 451383.75 | K45: 564229.69
A46: Wales | B46: Core Deposits | C46: 228285.9 | D46: 236601 | E46: 242037.9 | F46: 247410 | G46: 247410 | H46: 247410 | I46: 284326.2 | J46: 276410.7 | K46: 302326.2
A47: Wales | B47: Stockholder's Equity | C47: 25875 | D47: 21720 | E47: 28386 | F47: 29430 | G47: 20483 | H47: 21410 | I47: 32310 | J47: 33210 | K47: 34110
... A68: Northern Ireland | B68: Net Charge Offs / Average Total Loans | C68: 2 | D68: 1.4 | E68: 3 | F68: 2 | G68: 3 | H68: 2 | I68: 2.5 | J68: 1.6 | K68: 1.5

Sheet Plan
A1: Region | B1: Activity | C1: =OFFSET(Lists!$E$1,COLUMN()-2,0,1,1) -> FY 12 | D1: =OFFSET(Lists!$E$1,COLUMN()-2,0,1,1) -> FY 13 | E1: =OFFSET(Lists!$E$1,COLUMN()-2,0,1,1) -> FY 14 | F1: =OFFSET(Lists!$E$1,COLUMN()-2,0,1,1) -> FY 15 | G1: =OFFSET(Lists!$E$1,COLUMN()-2,0,1,1) -> FY 16 | H1: =OFFSET(Lists!$E$1,COLUMN()-2,0,1,1) -> FY 17 | I1: =OFFSET(Lists!$E$1,COLUMN()-2,0,1,1) -> FY 18 | J1: =OFFSET(Lists!$E$1,COLUMN()-2,0,1,1) -> FY 19 | K1: =OFFSET(Lists!$E$1,COLUMN()-2,0,1,1) -> FY 20
A2: England | B2: Net Income | C2: 7759.64 | D2: 8164.8 | E2: 8784.72 | F2: 9940.8 | G2: 10395.84 | H2: 9595 | I2: 10659 | J2: 10674.2 | K2: 10090.91
A3: England | B3: Revenue | C3: 28322 | D3: 32561.93 | E3: 32785.45 | F3: 34607.66 | G3: 37806.72 | H3: 39213.72 | I3: 40197.15 | J3: 41671.438 | K3: 46707.773
A4: England | B4: Diluted Earnings Per Share | C4: 2.945 | D4: 3.072 | E4: 3.1825 | F4: 3.264 | G4: 3.312 | H4: 3.528 | I4: 4.32 | J4: 5.5125 | K4: 6.6796875
A5: England | B5: Dividends Per Share | C5: 0.9603 | D5: 0.9975 | E5: 1.0656 | F5: 1.176 | G5: 1.2054 | H5: 1.2416 | I5: 1.568 | J5: 1.98 | K5: 2.4
A6: England | B6: Return on Assets | C6: 2.8028 | D6: 2.51136 | E6: 2.5441 | F6: 2.58875 | G6: 2.5725 | H6: 2.75418 | I6: 3.3345 | J6: 4.0210625 | K6: 5.4244531
A7: England | B7: Return on Equity | C7: 23.166 | D7: 21.565 | E7: 26.532 | F7: 25.443 | G7: 27.324 | H7: 27.456 | I7: 30.135 | J7: 25.430625 | K7: 22.402188
A8: England | B8: Net Interest Margin | C8: 7.125 | D8: 7.644 | E8: 7.968 | F8: 8.051 | G8: 8.316 | H8: 8.613 | I8: 8.78625 | J8: 8.64 | K8: 8.352
A9: England | B9: Efficiency Ratio | C9: 0.8316 | D9: 0.864 | E9: 0.8415 | F9: 0.8265 | G9: 0.8232 | H9: 0.836 | I9: 1.067 | J9: 1.33375 | K9: 1.65
A10: England | B10: Assets | C10: 466092 | D10: 506385 | E10: 512160 | F10: 539136 | G10: 564300 | H10: 619938 | I10: 661297.5 | J10: 704899 | K10: 648420
A11: England | B11: Loans | C11: 253363.77 | D11: 259863 | E11: 267744 | F11: 289802.05 | G11: 300384 | H11: 304934.8 | I11: 286168.5 | J11: 283826.75 | K11: 320383.44
A12: England | B12: Core Deposits | C12: 243504.96 | D12: 260261.1 | E12: 266241.69 | F12: 272151 | G12: 280475.5 | H12: 299799.64 | I12: 306440.46 | J12: 291766.85 | K12: 322481.28
A13: England | B13: Stockholder's Equity | C13: 27312.5 | D13: 30492 | E13: 31224.6 | F13: 32373 | G13: 32853.9 | H13: 34202 | I13: 35182 | J13: 35424 | K13: 36005
... A17: England | B17: Net Charge Offs / Average Total Loans | C17: 1.615 | D17: 1.372 | E17: 1.52 | F17: 1.552 | G17: 1.425 | H17: 1.33 | I17: 1.287 | J17: 1.52 | K17: 1.485
C18: 0 | D18: 0 | E18: 0 | F18: 0 | G18: 0 | H18: 0 | I18: 0 | J18: 0 | K18: 0
A19: Scotland | B19: Net Income | C19: 3296.7 | D19: 3574.935 | E19: 3779.82 | F19: 4330.08 | G19: 4554.3 | H19: 5068.25 | I19: 5107.2 | J19: 4602.24 | K19: 5068.25
A20: Scotland | B20: Revenue | C20: 12984.192 | D20: 16179.637 | E20: 16802.164 | F20: 17409.829 | G20: 19405.02 | H20: 19358.273 | I20: 23763.514 | J20: 17924.868 | K20: 19185.313
A21: Scotland | B21: Diluted Earnings Per Share | C21: 2.079 | D21: 2.09 | E21: 2.256 | F21: 2.304 | G21: 2.401 | H21: 3.04 | I21: 4.455 | J21: 5.56875 | K21: 3.528
A22: Scotland | B22: Dividends Per Share | C22: 0.669397 | D22: 0.769307 | E22: 0.869652 | F22: 0.97679 | G22: 0.662496 | H22: 0.769307 | I22: 0.912282 | J22: 0.959136 | K22: 1.087655
A23: Scotland | B23: Return on Assets | C23: 1.584 | D23: 1.683 | E23: 1.52 | F23: 1.485 | G23: 3.36 | H23: 3.456 | I23: 4.1225 | J23: 4.86 | K23: 5.7742188
A24: Scotland | B24: Return on Equity | C24: 21.504 | D24: 21.6 | E24: 25.026 | F24: 23.959 | G24: 28.314 | H24: 28.712 | I24: 31.4325 | J24: 25.886875 | K24: 22.666406
A25: Scotland | B25: Net Interest Margin | C25: 6.435 | D25: 6.534 | E25: 6.935 | F25: 7.227 | G25: 9.306 | H25: 9.409 | I25: 9.48 | J25: 9.5 | K25: 9.409
A26: Scotland | B26: Efficiency Ratio | C26: 1.558 | D26: 1.6878 | E26: 1.7848 | F26: 1.8818 | G26: 1.81778 | H26: 1.8236 | I26: 2.016 | J26: 2.3275 | K26: 2.1521875
A27: Scotland | B27: Assets | C27: 261900 | D27: 264600.1 | E27: 230400 | F27: 194000 | G27: 286150 | H27: 333200 | I27: 372000 | J27: 479531.25 | K27: 599414.06
A28: Scotland | B28: Loans | C28: 156381.89 | D28: 153222.75 | E28: 128155.5 | F28: 160913.38 | G28: 167627.5 | H28: 157282.16 | I28: 190584.25 | J28: 238230.31 | K28: 297787.89
A29: Scotland | B29: Core Deposits | C29: 156662.81 | D29: 146590.68 | E29: 158481.6 | F29: 148171.1 | G29: 168853.95 | H29: 155895.81 | I29: 147944.2 | J29: 153500.08 | K29: 156599.81
A30: Scotland | B30: Stockholder's Equity | C30: 13943.75 | D30: 13800.096 | E30: 15612.3 | F30: 16186.5 | G30: 16257.6 | H30: 16752 | I30: 17770.5 | J30: 17527.5 | K30: 18002.5
... A34: Scotland | B34: Net Charge Offs / Average Total Loans | C34: 0.686 | D34: 0.792 | E34: 0.57 | F34: 0.576 | G34: 2.4 | H34: 2.328 | I34: 2.231 | J34: 2.522 | K34: 2.45
C35: 0 | D35: 0 | E35: 0 | F35: 0 | G35: 0 | H35: 0 | I35: 0 | J35: 0 | K35: 0
A36: Wales | B36: Net Income | C36: 8058.6 | D36: 8642.7 | E36: 8856.1 | F36: 16063.2 | G36: 10883.4 | H36: 11858 | I36: 11950.4 | J36: 12122 | K36: 12853.5
A37: Wales | B37: Revenue | C37: 30836.3 | D37: 35079.605 | E37: 36823.237 | F37: 38460.884 | G37: 42016.128 | H37: 52264.63 | I37: 52818.48 | J37: 59303.1 | K37: 83388.551
A38: Wales | B38: Diluted Earnings Per Share | C38: 4.018 | D38: 4.074 | E38: 4.263 | F38: 4.18 | G38: 4.4055 | H38: 4.37 | I38: 5.39 | J38: 6.55875 | K38: 7.71
A39: Wales | B39: Dividends Per Share | C39: 1.949906 | D39: 2.0254 | E39: 2.287692 | F39: 2.448 | G39: 2.314517 | H39: 2.366412 | I39: 2.6208 | J39: 3.0555 | K39: 3.70755
A40: Wales | B40: Return on Assets | C40: 3.456 | D40: 3.332 | E40: 3.42 | F40: 3.395 | G40: 3.36 | H40: 3.492 | I40: 4.1225 | J40: 4.86 | K40: 5.8957812
A41: Wales | B41: Return on Equity | C41: 23.18 | D41: 22.752 | E41: 26.966 | F41: 26.433 | G41: 28.028 | H41: 29.008 | I41: 30.7975 | J41: 25.353125 | K41: 22.905
A42: Wales | B42: Net Interest Margin | C42: 9.0695 | D42: 8.53248 | E42: 9.29628 | F42: 9.38184 | G42: 9.9264 | H42: 9.5836 | I42: 10.1436 | J42: 10.67 | K42: 9.40512
A43: Wales | B43: Efficiency Ratio | C43: 1.7664 | D43: 1.862 | E43: 1.8315 | F43: 1.7952 | G43: 1.8032 | H43: 1.8612 | I43: 2.079 | J43: 2.35125 | K43: 2.664375
A44: Wales | B44: Assets | C44: 376200 | D44: 410130 | E44: 410400 | F44: 449280 | G44: 480150 | H44: 541260 | I44: 676575 | J44: 845718.75 | K44: 1035351.6
A45: Wales | B45: Loans | C45: 223420.78 | D45: 236287.8 | E45: 240969.6 | F45: 245989.8 | G45: 248499.9 | H45: 285996.74 | I45: 353884.86 | J45: 446869.91 | K45: 536018.2
A46: Wales | B46: Core Deposits | C46: 223720.18 | D46: 234234.99 | E46: 229936.01 | F46: 244935.9 | G46: 235039.5 | H46: 242461.8 | I46: 272953.15 | J46: 262590.16 | K46: 293256.41
...

Sheet Cust
A1: Satisfaction | B1: States | C1: PY | D1: CY
A2: Customer | B2: England | C2: 0.87 | D2: 0.83
A3: Customer | B3: Scotland | C3: 0.8 | D3: 0.85
A4: Customer | B4: Wales | C4: 0.88 | D4: 0.92
A5: Customer | B5: Northern Ireland | C5: 0.83 | D5: 0.81

Sheet Hires
A1: Type | B1: State | C1: {=TRANSPOSE(Lists!D2:D12)} -> FY 10 | D1: FY 11 | E1: FY 12 | F1: FY 13 | G1: FY 14 | H1: FY 15 | I1: FY 16 | J1: FY 17 | K1: FY 18 | L1: FY 19 | M1: FY 20
A2: Termination | B2: England | C2: -416.16 | D2: -234.78 | E2: -612 | F2: -511 | G2: -408 | H2: -301 | I2: -354 | J2: -102 | K2: -408 | L2: -102 | M2: -321
A3: New Hires | B3: England | C3: 599.76 | D3: 264.48 | E3: 408 | F3: 514 | G3: 612 | H3: 232 | I3: 387 | J3: 418 | K3: 714 | L3: 517 | M3: 411
A4: Termination | B4: Scotland | C4: -313.04 | D4: -189.72 | E4: -816 | F4: -301 | G4: -301 | H4: -204 | I4: -354 | J4: -204 | K4: -612 | L4: -102 | M4: -102
A5: New Hires | B5: Scotland | C5: 278.88 | D5: 220.9 | E5: 612 | F5: 714 | G5: 332 | H5: 235 | I5: 519 | J5: 412 | K5: 1020 | L5: 1122 | M5: 714
A6: Termination | B6: Wales | C6: -233.22 | D6: -357.12 | E6: -714 | F6: -312 | G6: -299 | H6: -288 | I6: -204 | J6: -354 | K6: -354 | L6: -102 | M6: -102
A7: New Hires | B7: Wales | C7: 473.28 | D7: 705.18 | E7: 455 | F7: 1122 | G7: 408 | H7: 511 | I7: 432 | J7: 612 | K7: 918 | L7: 1428 | M7: 714
A8: Termination | B8: Northern Ireland | C8: -534.48 | D8: -240.8 | E8: -408 | F8: -301 | G8: -408 | H8: -301 | I8: -298 | J8: -300 | K8: -204 | L8: -102 | M8: -204
A9: New Hires | B9: Northern Ireland | C9: 369.74 | D9: 257.52 | E9: 408 | F9: 1122 | G9: 278 | H9: 232 | I9: 333 | J9: 816 | K9: 714 | L9: 530 | M9: 714

Sheet Sick
A1: Avg Sick Days | B1: Country | C1: Jul | D1: Aug | E1: Sep | F1: Oct | G1: Nov | H1: Dec | I1: Jan | J1: Feb | K1: Mar | L1: Apr | M1: May | N1: Jun
A2: CY | B2: England | C2: 7.7616 | D2: 9.7944 | E2: 7.4844 | F2: 10.3488 | G2: 9.3324 | H2: 9.9792 | I2: 8.5008 | J2: 10.3488 | K2: 8.6856 | L2: 7.9464 | M2: 8.4084 | N2: 8.778
A3: CY | B3: Scotland | C3: 7.7 | D3: 8.9133 | E3: 6.5846 | F3: 8.9936 | G3: 8.9133 | H3: 9.0739 | I3: 7.6285 | J3: 8.9133 | K3: 6.6649 | L3: 6.5043 | M3: 8.2709 | N3: 8.5921
A4: CY | B4: Wales | C4: 5.9345 | D4: 6.5065 | E4: 6.9355 | F4: 6.5065 | G4: 7.007 | H4: 5.9345 | I4: 7.7935 | J4: 5.7915 | K4: 7.7935 | L4: 5.7915 | M4: 6.9355 | N4: 6.7925
A5: CY | B5: Northern Ireland | C5: 8.272 | D5: 9.328 | E5: 8.36 | F5: 8.8 | G5: 9.68 | H5: 9.944 | I5: 9.416 | J5: 10.032 | K5: 7.128 | L5: 10.472 | M5: 10.56 | N5: 7.04
A7: PY | B7: England | C7: 6.56208 | D7: 8.28072 | E7: 6.25968 | F7: 8.4672 | G7: 7.29624 | H7: 7.34832 | I7: 6.25968 | J7: 7.5264 | K7: 6.63264 | L7: 5.92368 | M7: 6.65028 | N7: 7.581
A8: PY | B8: Scotland | C8: 7.2 | D8: 7.37373 | E8: 6.46488 | F8: 7.68544 | G8: 7.69785 | H8: 7.75406 | I8: 6.2415 | J8: 8.75124 | K8: 5.57428 | L8: 5.73561 | M8: 6.7671 | N8: 7.49856
A9: PY | B9: Wales | C9: 4.6397 | D9: 5.02775 | E9: 5.48535 | F9: 5.5601 | G9: 5.9241 | H9: 5.12525 | I9: 6.02225 | J9: 4.26465 | K9: 6.2348 | L9: 4.8438 | M9: 5.98975 | N9: 5.61925
A10: PY | B10: Northern Ireland | C10: 7.2192 | D10: 8.904 | E10: 8.436 | F10: 7.76 | G10: 10.296 | H10: 9.3112 | I10: 9.0736 | J10: 9.3024 | K10: 6.156 | L10: 9.1392 | M10: 8.64 | N10: 6.016

Sheet FTE
A1: Region | B1: Metric | C1: Year | D1: Type | E1: Data
A2: England | B2: FTEs | C2: Prior Yr | D2: Actual | E2: 5217.7952
A3: England | B3: FTEs | C3: Prior Yr | D3: Plan | E3: 5098.3368
A4: England | B4: FTEs | C4: Cur Yr | D4: Actual | E4: 6942.3237
A5: England | B5: FTEs | C5: Cur Yr | D5: Plan | E5: 6973.1982
A6: England | B6: FTEs | C6: Cur Yr | D6: Forecast | E6: 6673.1982
A8: Scotland | B8: FTEs | C8: Prior Yr | D8: Actual | E8: 1721.8724
A9: Scotland | B9: FTEs | C9: Prior Yr | D9: Plan | E9: 1682.4511
A10: Scotland | B10: FTEs | C10: Cur Yr | D10: Actual | E10: 2290.9668
A11: Scotland | B11: FTEs | C11: Cur Yr | D11: Plan | E11: 2200
A12: Scotland | B12: FTEs | C12: Cur Yr | D12: Forecast | E12: 2202.1554
A14: Wales | B14: FTEs | C14: Prior Yr | D14: Actual | E14: 1147.9149
A15: Wales | B15: FTEs | C15: Prior Yr | D15: Plan | E15: 1121.6341
... A24: Northern Ireland | B24: FTEs | C24: Cur Yr | D24: Forecast | E24: 607.31982

Sheet General
A1: Region | B1: Operation | C1: % Result
A2: England | B2: Home Loans | C2: 0.12
A3: England | B3: Credit Cards | C3: 0.25
A4: England | B4: Houshold Lending | C4: 0.04
A5: England | B5: Other Bank Income | C5: 0.02
A6: England | B6: Retail Deposits | C6: 0.06
A7: England | B7: Business Lending | C7: 0.18
A8: England | B8: Asset Finance | C8: 0.2
A9: England | B9: Equities Trading | C9: 0.1
A10: England | B10: FX Trading | C10: 0.03
A12: Scotland | B12: Home Loans | C12: 0.18
A13: Scotland | B13: Credit Cards | C13: 0.22
A14: Scotland | B14: Houshold Lending | C14: 0.06
... A40: Northern Ireland | B40: FX Trading | C40: 0.1

Sheet Other
A1: Region | B1: Activity | C1: Current Mth
A2: England | B2: Interest Income | C2: 166.66667
A3: England | B3: Funds Mgt Income | C3: 333.33333
A4: England | B4: Insurance Income | C4: 250
A5: England | B5: Other Bank Income | C5: 83.333333
A6: England | B6: Net Income | C6: 833.33333
A7: England | B7: Operational Expenses | C7: 416.66667
A8: England | B8: Loan Imparement Expenses | C8: 104.16667
A9: England | B9: Net Expenses | C9: 520.83333
A10: England | B10: Net Profit | C10: 312.5
A12: Scotland | B12: Interest Income | C12: =Data!$H$19/12*0.2 -> 87.083333
A13: Scotland | B13: Funds Mgt Income | C13: =Data!$H$19/12*0.4 -> 174.16667
A14: Scotland | B14: Insurance Income | C14: =Data!$H$19/12*0.3 -> 130.625
A15: Scotland | B15: Other Bank Income | C15: =Data!$H$19/12*0.1 -> 43.541667
A16: Scotland | B16: Net Income | C16: =SUM(C12:C15) -> 435.41667
A17: Scotland | B17: Operational Expenses | C17: =C16/2 -> 217.70833
A18: Scotland | B18: Loan Imparement Expenses | C18: =C17/4 -> 54.427083
A19: Scotland | B19: Net Expenses | C19: =SUM(C17:C18) -> 272.13542
A20: Scotland | B20: Net Profit | C20: =C16-C19 -> 163.28125
A22: Wales | B22: Interest Income | C22: =Data!$H$36/12*0.2 -> 201.66667
A23: Wales | B23: Funds Mgt Income | C23: =Data!$H$36/12*0.4 -> 403.33333
A24: Wales | B24: Insurance Income | C24: =Data!$H$36/12*0.3 -> 302.5
A25: Wales | B25: Other Bank Income | C25: =Data!$H$36/12*0.1 -> 100.83333
A26: Wales | B26: Net Income | C26: =SUM(C22:C25) -> 1008.3333
A27: Wales | B27: Operational Expenses | C27: =C26/2 -> 504.16667
A28: Wales | B28: Loan Imparement Expenses | C28: =C27/4 -> 126.04167
A29: Wales | B29: Net Expenses | C29: =SUM(C27:C28) -> 630.20833
A30: Wales | B30: Net Profit | C30: =C26-C29 -> 378.125
A32: Northern Ireland | B32: Interest Income | C32: =Data!$H$53/12*0.2 -> 183.33333
A33: Northern Ireland | B33: Funds Mgt Income | C33: =Data!$H$53/12*0.4 -> 366.66667
A34: Northern Ireland | B34: Insurance Income | C34: =Data!$H$53/12*0.3 -> 275
A35: Northern Ireland | B35: Other Bank Income | C35: =Data!$H$53/12*0.1 -> 91.666667
A36: Northern Ireland | B36: Net Income | C36: =SUM(C32:C35) -> 916.66667
A37: Northern Ireland | B37: Operational Expenses | C37: =C36/2 -> 458.33333
A38: Northern Ireland | B38: Loan Imparement Expenses | C38: =C37/4 -> 114.58333
A39: Northern Ireland | B39: Net Expenses | C39: =SUM(C37:C38) -> 572.91667
A40: Northern Ireland | B40: Net Profit | C40: =C36-C39 -> 343.75

Sheet Calcs
A2: Graph Data | B2: =Summary!J10 -> FY 14 | C2: =Summary!K10 -> FY 15 | D2: =Summary!L10 -> FY 16 | E2: =Summary!M10 -> FY 17 | F2: =Summary!N10 -> FY 18 | G2: =Summary!O10 -> FY 19
A3: =Lists!B3 -> Core Deposits | B3: =SUMPRODUCT((Data!$B$2:$B$68=$A3)*(Data!$A$2:$A$68=$A$7)*(Data!$C$1:$K$1=B$2)*(Data!$C$2:$K$68)) -> 154465.5 | C3: =SUMPRODUCT((Data!$B$2:$B$68=$A3)*(Data!$A$2:$A$68=$A$7)*(Data!$C$1:$K$1=C$2)*(Data!$C$2:$K$68)) -> 137450 | D3: =SUMPRODUCT((Data!$B$2:$B$68=$A3)*(Data!$A$2:$A$68=$A$7)*(Data!$C$1:$K$1=D$2)*(Data!$C$2:$K$68)) -> 164575 | E3: =SUMPRODUCT((Data!$B$2:$B$68=$A3)*(Data!$A$2:$A$68=$A$7)*(Data!$C$1:$K$1=E$2)*(Data!$C$2:$K$68)) -> 152959 | F3: =SUMPRODUCT((Data!$B$2:$B$68=$A3)*(Data!$A$2:$A$68=$A$7)*(Data!$C$1:$K$1=F$2)*(Data!$C$2:$K$68)) -> 147959 | G3: =SUMPRODUCT((Data!$B$2:$B$68=$A3)*(Data!$A$2:$A$68=$A$7)*(Data!$C$1:$K$1=G$2)*(Data!$C$2:$K$68)) -> 153561.5
A4: Plan | B4: =SUMPRODUCT((Plan!$B$2:$B$68=$A3)*(Plan!$A$2:$A$68=$A$7)*(Plan!$C$1:$K$1=B$2)*(Plan!$C$2:$K$68)) -> 158481.6 | C4: =SUMPRODUCT((Plan!$B$2:$B$68=$A3)*(Plan!$A$2:$A$68=$A$7)*(Plan!$C$1:$K$1=C$2)*(Plan!$C$2:$K$68)) -> 148171.1 | D4: =SUMPRODUCT((Plan!$B$2:$B$68=$A3)*(Plan!$A$2:$A$68=$A$7)*(Plan!$C$1:$K$1=D$2)*(Plan!$C$2:$K$68)) -> 168853.95 | E4: =SUMPRODUCT((Plan!$B$2:$B$68=$A3)*(Plan!$A$2:$A$68=$A$7)*(Plan!$C$1:$K$1=E$2)*(Plan!$C$2:$K$68)) -> 155895.81 | F4: =SUMPRODUCT((Plan!$B$2:$B$68=$A3)*(Plan!$A$2:$A$68=$A$7)*(Plan!$C$1:$K$1=F$2)*(Plan!$C$2:$K$68)) -> 147944.2 | G4: =SUMPRODUCT((Plan!$B$2:$B$68=$A3)*(Plan!$A$2:$A$68=$A$7)*(Plan!$C$1:$K$1=G$2)*(Plan!$C$2:$K$68)) -> 153500.08
A7: =Lists!B5 -> Scotland | B7: =Data!C1 -> FY 12 | C7: =Data!D1 -> FY 13 | D7: =Data!E1 -> FY 14 | E7: =Data!F1 -> FY 15 | F7: =Data!G1 -> FY 16 | G7: =Data!H1 -> FY 17 | H7: =Data!I1 -> FY 18 | I7: =Data!J1 -> FY 19 | J7: =Data!K1 -> FY 20
A8: Net Income | B8: =SUMPRODUCT((Data!$B$2:$B$68=$A8)*(Data!$A$2:$A$68=$A$7)*(Data!C$2:C$68)) -> 3330 | C8: =SUMPRODUCT((Data!$B$2:$B$68=$A8)*(Data!$A$2:$A$68=$A$7)*(Data!D$2:D$68)) -> 3685.5 | D8: =SUMPRODUCT((Data!$B$2:$B$68=$A8)*(Data!$A$2:$A$68=$A$7)*(Data!E$2:E$68)) -> 3818 | E8: =SUMPRODUCT((Data!$B$2:$B$68=$A8)*(Data!$A$2:$A$68=$A$7)*(Data!F$2:F$68)) -> 4464 | F8: =SUMPRODUCT((Data!$B$2:$B$68=$A8)*(Data!$A$2:$A$68=$A$7)*(Data!G$2:G$68)) -> 4794 | G8: =SUMPRODUCT((Data!$B$2:$B$68=$A8)*(Data!$A$2:$A$68=$A$7)*(Data!H$2:H$68)) -> 5225 | H8: =SUMPRODUCT((Data!$B$2:$B$68=$A8)*(Data!$A$2:$A$68=$A$7)*(Data!I$2:I$68)) -> 5376 | I8: =SUMPRODUCT((Data!$B$2:$B$68=$A8)*(Data!$A$2:$A$68=$A$7)*(Data!J$2:J$68)) -> 4794 | J8: =SUMPRODUCT((Data!$B$2:$B$68=$A8)*(Data!$A$2:$A$68=$A$7)*(Data!K$2:K$68)) -> 5225
A9: Revenue | B9: =SUMPRODUCT((Data!$B$2:$B$68=$A9)*(Data!$A$2:$A$68=$A$7)*(Data!C$2:C$68)) -> 13005 | C9: =SUMPRODUCT((Data!$B$2:$B$68=$A9)*(Data!$A$2:$A$68=$A$7)*(Data!D$2:D$68)) -> 15273.895 | D9: =SUMPRODUCT((Data!$B$2:$B$68=$A9)*(Data!$A$2:$A$68=$A$7)*(Data!E$2:E$68)) -> 15875.06 | E9: =SUMPRODUCT((Data!$B$2:$B$68=$A9)*(Data!$A$2:$A$68=$A$7)*(Data!F$2:F$68)) -> 16590.27 | F9: =SUMPRODUCT((Data!$B$2:$B$68=$A9)*(Data!$A$2:$A$68=$A$7)*(Data!G$2:G$68)) -> 18318.72 | G9: =SUMPRODUCT((Data!$B$2:$B$68=$A9)*(Data!$A$2:$A$68=$A$7)*(Data!H$2:H$68)) -> 19006.65 | H9: =SUMPRODUCT((Data!$B$2:$B$68=$A9)*(Data!$A$2:$A$68=$A$7)*(Data!I$2:I$68)) -> 24008.4 | I9: =SUMPRODUCT((Data!$B$2:$B$68=$A9)*(Data!$A$2:$A$68=$A$7)*(Data!J$2:J$68)) -> 18318.72 | J9: =SUMPRODUCT((Data!$B$2:$B$68=$A9)*(Data!$A$2:$A$68=$A$7)*(Data!K$2:K$68)) -> 19006.65
A10: Diluted Earnings Per Share | B10: =SUMPRODUCT((Data!$B$2:$B$68=$A10)*(Data!$A$2:$A$68=$A$7)*(Data!C$2:C$68)) -> 2.1 | C10: =SUMPRODUCT((Data!$B$2:$B$68=$A10)*(Data!$A$2:$A$68=$A$7)*(Data!D$2:D$68)) -> 2.2 | D10: =SUMPRODUCT((Data!$B$2:$B$68=$A10)*(Data!$A$2:$A$68=$A$7)*(Data!E$2:E$68)) -> 2.35 | E10: =SUMPRODUCT((Data!$B$2:$B$68=$A10)*(Data!$A$2:$A$68=$A$7)*(Data!F$2:F$68)) -> 2.4 | F10: =SUMPRODUCT((Data!$B$2:$B$68=$A10)*(Data!$A$2:$A$68=$A$7)*(Data!G$2:G$68)) -> 2.45 | G10: =SUMPRODUCT((Data!$B$2:$B$68=$A10)*(Data!$A$2:$A$68=$A$7)*(Data!H$2:H$68)) -> 3.2 | H10: =SUMPRODUCT((Data!$B$2:$B$68=$A10)*(Data!$A$2:$A$68=$A$7)*(Data!I$2:I$68)) -> 4.5 | I10: =SUMPRODUCT((Data!$B$2:$B$68=$A10)*(Data!$A$2:$A$68=$A$7)*(Data!J$2:J$68)) -> 5.625 | J10: =SUMPRODUCT((Data!$B$2:$B$68=$A10)*(Data!$A$2:$A$68=$A$7)*(Data!K$2:K$68)) -> 3.6
A11: Dividends Per Share | B11: =SUMPRODUCT((Data!$B$2:$B$68=$A11)*(Data!$A$2:$A$68=$A$7)*(Data!C$2:C$68)) -> 0.67 | C11: =SUMPRODUCT((Data!$B$2:$B$68=$A11)*(Data!$A$2:$A$68=$A$7)*(Data!D$2:D$68)) -> 0.77 | D11: =SUMPRODUCT((Data!$B$2:$B$68=$A11)*(Data!$A$2:$A$68=$A$7)*(Data!E$2:E$68)) -> 0.87 | E11: =SUMPRODUCT((Data!$B$2:$B$68=$A11)*(Data!$A$2:$A$68=$A$7)*(Data!F$2:F$68)) -> 0.97 | F11: =SUMPRODUCT((Data!$B$2:$B$68=$A11)*(Data!$A$2:$A$68=$A$7)*(Data!G$2:G$68)) -> 0.67 | G11: =SUMPRODUCT((Data!$B$2:$B$68=$A11)*(Data!$A$2:$A$68=$A$7)*(Data!H$2:H$68)) -> 0.77 | H11: =SUMPRODUCT((Data!$B$2:$B$68=$A11)*(Data!$A$2:$A$68=$A$7)*(Data!I$2:I$68)) -> 0.87 | I11: =SUMPRODUCT((Data!$B$2:$B$68=$A11)*(Data!$A$2:$A$68=$A$7)*(Data!J$2:J$68)) -> 0.97 | J11: =SUMPRODUCT((Data!$B$2:$B$68=$A11)*(Data!$A$2:$A$68=$A$7)*(Data!K$2:K$68)) -> 1.07
A12: Return on Assets | B12: =SUMPRODUCT((Data!$B$2:$B$68=$A12)*(Data!$A$2:$A$68=$A$7)*(Data!C$2:C$68)) -> 1.6 | C12: =SUMPRODUCT((Data!$B$2:$B$68=$A12)*(Data!$A$2:$A$68=$A$7)*(Data!D$2:D$68)) -> 1.7 | D12: =SUMPRODUCT((Data!$B$2:$B$68=$A12)*(Data!$A$2:$A$68=$A$7)*(Data!E$2:E$68)) -> 1.6 | E12: =SUMPRODUCT((Data!$B$2:$B$68=$A12)*(Data!$A$2:$A$68=$A$7)*(Data!F$2:F$68)) -> 1.5 | F12: =SUMPRODUCT((Data!$B$2:$B$68=$A12)*(Data!$A$2:$A$68=$A$7)*(Data!G$2:G$68)) -> 3.5 | G12: =SUMPRODUCT((Data!$B$2:$B$68=$A12)*(Data!$A$2:$A$68=$A$7)*(Data!H$2:H$68)) -> 3.6 | H12: =SUMPRODUCT((Data!$B$2:$B$68=$A12)*(Data!$A$2:$A$68=$A$7)*(Data!I$2:I$68)) -> 4.25 | I12: =SUMPRODUCT((Data!$B$2:$B$68=$A12)*(Data!$A$2:$A$68=$A$7)*(Data!J$2:J$68)) -> 5.0625 | J12: =SUMPRODUCT((Data!$B$2:$B$68=$A12)*(Data!$A$2:$A$68=$A$7)*(Data!K$2:K$68)) -> 6.078125
A13: Return on Equity | B13: =SUMPRODUCT((Data!$B$2:$B$68=$A13)*(Data!$A$2:$A$68=$A$7)*(Data!C$2:C$68)) -> 22.4 | C13: =SUMPRODUCT((Data!$B$2:$B$68=$A13)*(Data!$A$2:$A$68=$A$7)*(Data!D$2:D$68)) -> 22.5 | D13: =SUMPRODUCT((Data!$B$2:$B$68=$A13)*(Data!$A$2:$A$68=$A$7)*(Data!E$2:E$68)) -> 25.8 | E13: =SUMPRODUCT((Data!$B$2:$B$68=$A13)*(Data!$A$2:$A$68=$A$7)*(Data!F$2:F$68)) -> 24.7 | F13: =SUMPRODUCT((Data!$B$2:$B$68=$A13)*(Data!$A$2:$A$68=$A$7)*(Data!G$2:G$68)) -> 28.6 | G13: =SUMPRODUCT((Data!$B$2:$B$68=$A13)*(Data!$A$2:$A$68=$A$7)*(Data!H$2:H$68)) -> 29.6 | H13: =SUMPRODUCT((Data!$B$2:$B$68=$A13)*(Data!$A$2:$A$68=$A$7)*(Data!I$2:I$68)) -> 31.75 | I13: =SUMPRODUCT((Data!$B$2:$B$68=$A13)*(Data!$A$2:$A$68=$A$7)*(Data!J$2:J$68)) -> 26.6875 | J13: =SUMPRODUCT((Data!$B$2:$B$68=$A13)*(Data!$A$2:$A$68=$A$7)*(Data!K$2:K$68)) -> 23.859375
A14: Net Interest Margin | B14: =SUMPRODUCT((Data!$B$2:$B$68=$A14)*(Data!$A$2:$A$68=$A$7)*(Data!C$2:C$68)) -> 6.5 | C14: =SUMPRODUCT((Data!$B$2:$B$68=$A14)*(Data!$A$2:$A$68=$A$7)*(Data!D$2:D$68)) -> 6.6 | D14: =SUMPRODUCT((Data!$B$2:$B$68=$A14)*(Data!$A$2:$A$68=$A$7)*(Data!E$2:E$68)) -> 7.3 | E14: =SUMPRODUCT((Data!$B$2:$B$68=$A14)*(Data!$A$2:$A$68=$A$7)*(Data!F$2:F$68)) -> 7.3 | F14: =SUMPRODUCT((Data!$B$2:$B$68=$A14)*(Data!$A$2:$A$68=$A$7)*(Data!G$2:G$68)) -> 9.4 | G14: =SUMPRODUCT((Data!$B$2:$B$68=$A14)*(Data!$A$2:$A$68=$A$7)*(Data!H$2:H$68)) -> 9.7 | H14: =SUMPRODUCT((Data!$B$2:$B$68=$A14)*(Data!$A$2:$A$68=$A$7)*(Data!I$2:I$68)) -> 9.875 | I14: =SUMPRODUCT((Data!$B$2:$B$68=$A14)*(Data!$A$2:$A$68=$A$7)*(Data!J$2:J$68)) -> 10 | J14: =SUMPRODUCT((Data!$B$2:$B$68=$A14)*(Data!$A$2:$A$68=$A$7)*(Data!K$2:K$68)) -> 9.7
A15: Efficiency Ratio | B15: =SUMPRODUCT((Data!$B$2:$B$68=$A15)*(Data!$A$2:$A$68=$A$7)*(Data!C$2:C$68)) -> 1.64 | C15: =SUMPRODUCT((Data!$B$2:$B$68=$A15)*(Data!$A$2:$A$68=$A$7)*(Data!D$2:D$68)) -> 1.74 | D15: =SUMPRODUCT((Data!$B$2:$B$68=$A15)*(Data!$A$2:$A$68=$A$7)*(Data!E$2:E$68)) -> 1.84 | E15: =SUMPRODUCT((Data!$B$2:$B$68=$A15)*(Data!$A$2:$A$68=$A$7)*(Data!F$2:F$68)) -> 1.94 | F15: =SUMPRODUCT((Data!$B$2:$B$68=$A15)*(Data!$A$2:$A$68=$A$7)*(Data!G$2:G$68)) -> 1.874 | G15: =SUMPRODUCT((Data!$B$2:$B$68=$A15)*(Data!$A$2:$A$68=$A$7)*(Data!H$2:H$68)) -> 1.88 | H15: =SUMPRODUCT((Data!$B$2:$B$68=$A15)*(Data!$A$2:$A$68=$A$7)*(Data!I$2:I$68)) -> 2.1 | I15: =SUMPRODUCT((Data!$B$2:$B$68=$A15)*(Data!$A$2:$A$68=$A$7)*(Data!J$2:J$68)) -> 2.375 | J15: =SUMPRODUCT((Data!$B$2:$B$68=$A15)*(Data!$A$2:$A$68=$A$7)*(Data!K$2:K$68)) -> 2.21875
A16: Assets | B16: =SUMPRODUCT((Data!$B$2:$B$68=$A16)*(Data!$A$2:$A$68=$A$7)*(Data!C$2:C$68)) -> 270000 | C16: =SUMPRODUCT((Data!$B$2:$B$68=$A16)*(Data!$A$2:$A$68=$A$7)*(Data!D$2:D$68)) -> 270000.1 | D16: =SUMPRODUCT((Data!$B$2:$B$68=$A16)*(Data!$A$2:$A$68=$A$7)*(Data!E$2:E$68)) -> 240000 | E16: =SUMPRODUCT((Data!$B$2:$B$68=$A16)*(Data!$A$2:$A$68=$A$7)*(Data!F$2:F$68)) -> 200000 | F16: =SUMPRODUCT((Data!$B$2:$B$68=$A16)*(Data!$A$2:$A$68=$A$7)*(Data!G$2:G$68)) -> 295000 | G16: =SUMPRODUCT((Data!$B$2:$B$68=$A16)*(Data!$A$2:$A$68=$A$7)*(Data!H$2:H$68)) -> 340000 | H16: =SUMPRODUCT((Data!$B$2:$B$68=$A16)*(Data!$A$2:$A$68=$A$7)*(Data!I$2:I$68)) -> 387500 | I16: =SUMPRODUCT((Data!$B$2:$B$68=$A16)*(Data!$A$2:$A$68=$A$7)*(Data!J$2:J$68)) -> 484375 | J16: =SUMPRODUCT((Data!$B$2:$B$68=$A16)*(Data!$A$2:$A$68=$A$7)*(Data!K$2:K$68)) -> 605468.75
A17: Loans | B17: =SUMPRODUCT((Data!$B$2:$B$68=$A17)*(Data!$A$2:$A$68=$A$7)*(Data!C$2:C$68)) -> 157961.5 | C17: =SUMPRODUCT((Data!$B$2:$B$68=$A17)*(Data!$A$2:$A$68=$A$7)*(Data!D$2:D$68)) -> 157961.6 | D17: =SUMPRODUCT((Data!$B$2:$B$68=$A17)*(Data!$A$2:$A$68=$A$7)*(Data!E$2:E$68)) -> 129450 | E17: =SUMPRODUCT((Data!$B$2:$B$68=$A17)*(Data!$A$2:$A$68=$A$7)*(Data!F$2:F$68)) -> 169382.5 | F17: =SUMPRODUCT((Data!$B$2:$B$68=$A17)*(Data!$A$2:$A$68=$A$7)*(Data!G$2:G$68)) -> 176450 | G17: =SUMPRODUCT((Data!$B$2:$B$68=$A17)*(Data!$A$2:$A$68=$A$7)*(Data!H$2:H$68)) -> 160492 | H17: =SUMPRODUCT((Data!$B$2:$B$68=$A17)*(Data!$A$2:$A$68=$A$7)*(Data!I$2:I$68)) -> 200615 | I17: =SUMPRODUCT((Data!$B$2:$B$68=$A17)*(Data!$A$2:$A$68=$A$7)*(Data!J$2:J$68)) -> 250768.75 | J17: =SUMPRODUCT((Data!$B$2:$B$68=$A17)*(Data!$A$2:$A$68=$A$7)*(Data!K$2:K$68)) -> 313460.94
A18: Core Deposits | B18: =SUMPRODUCT((Data!$B$2:$B$68=$A18)*(Data!$A$2:$A$68=$A$7)*(Data!C$2:C$68)) -> 146825.5 | C18: =SUMPRODUCT((Data!$B$2:$B$68=$A18)*(Data!$A$2:$A$68=$A$7)*(Data!D$2:D$68)) -> 146825.6 | D18: =SUMPRODUCT((Data!$B$2:$B$68=$A18)*(Data!$A$2:$A$68=$A$7)*(Data!E$2:E$68)) -> 154465.5 | E18: =SUMPRODUCT((Data!$B$2:$B$68=$A18)*(Data!$A$2:$A$68=$A$7)*(Data!F$2:F$68)) -> 137450 | F18: =SUMPRODUCT((Data!$B$2:$B$68=$A18)*(Data!$A$2:$A$68=$A$7)*(Data!G$2:G$68)) -> 164575 | G18: =SUMPRODUCT((Data!$B$2:$B$68=$A18)*(Data!$A$2:$A$68=$A$7)*(Data!H$2:H$68)) -> 152959 | H18: =SUMPRODUCT((Data!$B$2:$B$68=$A18)*(Data!$A$2:$A$68=$A$7)*(Data!I$2:I$68)) -> 147959 | I18: =SUMPRODUCT((Data!$B$2:$B$68=$A18)*(Data!$A$2:$A$68=$A$7)*(Data!J$2:J$68)) -> 153561.5 | J18: =SUMPRODUCT((Data!$B$2:$B$68=$A18)*(Data!$A$2:$A$68=$A$7)*(Data!K$2:K$68)) -> 147959
A19: Stockholder's Equity | B19: =SUMPRODUCT((Data!$B$2:$B$68=$A19)*(Data!$A$2:$A$68=$A$7)*(Data!C$2:C$68)) -> 14375 | C19: =SUMPRODUCT((Data!$B$2:$B$68=$A19)*(Data!$A$2:$A$68=$A$7)*(Data!D$2:D$68)) -> 14375.1 | D19: =SUMPRODUCT((Data!$B$2:$B$68=$A19)*(Data!$A$2:$A$68=$A$7)*(Data!E$2:E$68)) -> 15770 | E19: =SUMPRODUCT((Data!$B$2:$B$68=$A19)*(Data!$A$2:$A$68=$A$7)*(Data!F$2:F$68)) -> 16350 | F19: =SUMPRODUCT((Data!$B$2:$B$68=$A19)*(Data!$A$2:$A$68=$A$7)*(Data!G$2:G$68)) -> 16935 | G19: =SUMPRODUCT((Data!$B$2:$B$68=$A19)*(Data!$A$2:$A$68=$A$7)*(Data!H$2:H$68)) -> 17450 | H19: =SUMPRODUCT((Data!$B$2:$B$68=$A19)*(Data!$A$2:$A$68=$A$7)*(Data!I$2:I$68)) -> 17950 | I19: =SUMPRODUCT((Data!$B$2:$B$68=$A19)*(Data!$A$2:$A$68=$A$7)*(Data!J$2:J$68)) -> 18450 | J19: =SUMPRODUCT((Data!$B$2:$B$68=$A19)*(Data!$A$2:$A$68=$A$7)*(Data!K$2:K$68)) -> 18950
... A23: Net Charge Offs / Average Total Loans | B23: =SUMPRODUCT((Data!$B$2:$B$68=$A23)*(Data!$A$2:$A$68=$A$7)*(Data!C$2:C$68)) -> 0.7 | C23: =SUMPRODUCT((Data!$B$2:$B$68=$A23)*(Data!$A$2:$A$68=$A$7)*(Data!D$2:D$68)) -> 0.8 | D23: =SUMPRODUCT((Data!$B$2:$B$68=$A23)*(Data!$A$2:$A$68=$A$7)*(Data!E$2:E$68)) -> 0.6 | E23: =SUMPRODUCT((Data!$B$2:$B$68=$A23)*(Data!$A$2:$A$68=$A$7)*(Data!F$2:F$68)) -> 0.6 | F23: =SUMPRODUCT((Data!$B$2:$B$68=$A23)*(Data!$A$2:$A$68=$A$7)*(Data!G$2:G$68)) -> 2.5 | G23: =SUMPRODUCT((Data!$B$2:$B$68=$A23)*(Data!$A$2:$A$68=$A$7)*(Data!H$2:H$68)) -> 2.4 | H23: =SUMPRODUCT((Data!$B$2:$B$68=$A23)*(Data!$A$2:$A$68=$A$7)*(Data!I$2:I$68)) -> 2.3 | I23: =SUMPRODUCT((Data!$B$2:$B$68=$A23)*(Data!$A$2:$A$68=$A$7)*(Data!J$2:J$68)) -> 2.6 | J23: =SUMPRODUCT((Data!$B$2:$B$68=$A23)*(Data!$A$2:$A$68=$A$7)*(Data!K$2:K$68)) -> 2.5
A26: Chart | B26: =B2 -> FY 14 | C26: =C2 -> FY 15 | D26: =D2 -> FY 16 | E26: =E2 -> FY 17 | F26: =F2 -> FY 18 | G26: =G2 -> FY 19
A27: Net Income | B27: =INDEX($A$8:$J$23,MATCH($A27,$A$8:$A$23,0),MATCH(B$26,$B$7:$J$7,0)+1) -> 3818 | C27: =INDEX($A$8:$J$23,MATCH($A27,$A$8:$A$23,0),MATCH(C$26,$B$7:$J$7,0)+1) -> 4464 | D27: =INDEX($A$8:$J$23,MATCH($A27,$A$8:$A$23,0),MATCH(D$26,$B$7:$J$7,0)+1) -> 4794 | E27: =INDEX($A$8:$J$23,MATCH($A27,$A$8:$A$23,0),MATCH(E$26,$B$7:$J$7,0)+1) -> 5225 | F27: =INDEX($A$8:$J$23,MATCH($A27,$A$8:$A$23,0),MATCH(F$26,$B$7:$J$7,0)+1) -> 5376 | G27: =INDEX($A$8:$J$23,MATCH($A27,$A$8:$A$23,0),MATCH(G$26,$B$7:$J$7,0)+1) -> 4794
A28: Revenue | B28: =INDEX($A$8:$J$23,MATCH($A28,$A$8:$A$23,0),MATCH(B$26,$B$7:$J$7,0)+1) -> 15875.06 | C28: =INDEX($A$8:$J$23,MATCH($A28,$A$8:$A$23,0),MATCH(C$26,$B$7:$J$7,0)+1) -> 16590.27 | D28: =INDEX($A$8:$J$23,MATCH($A28,$A$8:$A$23,0),MATCH(D$26,$B$7:$J$7,0)+1) -> 18318.72 | E28: =INDEX($A$8:$J$23,MATCH($A28,$A$8:$A$23,0),MATCH(E$26,$B$7:$J$7,0)+1) -> 19006.65 | F28: =INDEX($A$8:$J$23,MATCH($A28,$A$8:$A$23,0),MATCH(F$26,$B$7:$J$7,0)+1) -> 24008.4 | G28: =INDEX($A$8:$J$23,MATCH($A28,$A$8:$A$23,0),MATCH(G$26,$B$7:$J$7,0)+1) -> 18318.72
A29: Diluted Earnings Per Share | B29: =INDEX($A$8:$J$23,MATCH($A29,$A$8:$A$23,0),MATCH(B$26,$B$7:$J$7,0)+1) -> 2.35 | C29: =INDEX($A$8:$J$23,MATCH($A29,$A$8:$A$23,0),MATCH(C$26,$B$7:$J$7,0)+1) -> 2.4 | D29: =INDEX($A$8:$J$23,MATCH($A29,$A$8:$A$23,0),MATCH(D$26,$B$7:$J$7,0)+1) -> 2.45 | E29: =INDEX($A$8:$J$23,MATCH($A29,$A$8:$A$23,0),MATCH(E$26,$B$7:$J$7,0)+1) -> 3.2 | F29: =INDEX($A$8:$J$23,MATCH($A29,$A$8:$A$23,0),MATCH(F$26,$B$7:$J$7,0)+1) -> 4.5 | G29: =INDEX($A$8:$J$23,MATCH($A29,$A$8:$A$23,0),MATCH(G$26,$B$7:$J$7,0)+1) -> 5.625
A30: Dividends Per Share | B30: =INDEX($A$8:$J$23,MATCH($A30,$A$8:$A$23,0),MATCH(B$26,$B$7:$J$7,0)+1) -> 0.87 | C30: =INDEX($A$8:$J$23,MATCH($A30,$A$8:$A$23,0),MATCH(C$26,$B$7:$J$7,0)+1) -> 0.97 | D30: =INDEX($A$8:$J$23,MATCH($A30,$A$8:$A$23,0),MATCH(D$26,$B$7:$J$7,0)+1) -> 0.67 | E30: =INDEX($A$8:$J$23,MATCH($A30,$A$8:$A$23,0),MATCH(E$26,$B$7:$J$7,0)+1) -> 0.77 | F30: =INDEX($A$8:$J$23,MATCH($A30,$A$8:$A$23,0),MATCH(F$26,$B$7:$J$7,0)+1) -> 0.87 | G30: =INDEX($A$8:$J$23,MATCH($A30,$A$8:$A$23,0),MATCH(G$26,$B$7:$J$7,0)+1) -> 0.97
A31: Return on Assets | B31: =INDEX($A$8:$J$23,MATCH($A31,$A$8:$A$23,0),MATCH(B$26,$B$7:$J$7,0)+1) -> 1.6 | C31: =INDEX($A$8:$J$23,MATCH($A31,$A$8:$A$23,0),MATCH(C$26,$B$7:$J$7,0)+1) -> 1.5 | D31: =INDEX($A$8:$J$23,MATCH($A31,$A$8:$A$23,0),MATCH(D$26,$B$7:$J$7,0)+1) -> 3.5 | E31: =INDEX($A$8:$J$23,MATCH($A31,$A$8:$A$23,0),MATCH(E$26,$B$7:$J$7,0)+1) -> 3.6 | F31: =INDEX($A$8:$J$23,MATCH($A31,$A$8:$A$23,0),MATCH(F$26,$B$7:$J$7,0)+1) -> 4.25 | G31: =INDEX($A$8:$J$23,MATCH($A31,$A$8:$A$23,0),MATCH(G$26,$B$7:$J$7,0)+1) -> 5.0625
A32: Return on Equity | B32: =INDEX($A$8:$J$23,MATCH($A32,$A$8:$A$23,0),MATCH(B$26,$B$7:$J$7,0)+1) -> 25.8 | C32: =INDEX($A$8:$J$23,MATCH($A32,$A$8:$A$23,0),MATCH(C$26,$B$7:$J$7,0)+1) -> 24.7 | D32: =INDEX($A$8:$J$23,MATCH($A32,$A$8:$A$23,0),MATCH(D$26,$B$7:$J$7,0)+1) -> 28.6 | E32: =INDEX($A$8:$J$23,MATCH($A32,$A$8:$A$23,0),MATCH(E$26,$B$7:$J$7,0)+1) -> 29.6 | F32: =INDEX($A$8:$J$23,MATCH($A32,$A$8:$A$23,0),MATCH(F$26,$B$7:$J$7,0)+1) -> 31.75 | G32: =INDEX($A$8:$J$23,MATCH($A32,$A$8:$A$23,0),MATCH(G$26,$B$7:$J$7,0)+1) -> 26.6875
A33: Net Interest Margin | B33: =INDEX($A$8:$J$23,MATCH($A33,$A$8:$A$23,0),MATCH(B$26,$B$7:$J$7,0)+1) -> 7.3 | C33: =INDEX($A$8:$J$23,MATCH($A33,$A$8:$A$23,0),MATCH(C$26,$B$7:$J$7,0)+1) -> 7.3 | D33: =INDEX($A$8:$J$23,MATCH($A33,$A$8:$A$23,0),MATCH(D$26,$B$7:$J$7,0)+1) -> 9.4 | E33: =INDEX($A$8:$J$23,MATCH($A33,$A$8:$A$23,0),MATCH(E$26,$B$7:$J$7,0)+1) -> 9.7 | F33: =INDEX($A$8:$J$23,MATCH($A33,$A$8:$A$23,0),MATCH(F$26,$B$7:$J$7,0)+1) -> 9.875 | G33: =INDEX($A$8:$J$23,MATCH($A33,$A$8:$A$23,0),MATCH(G$26,$B$7:$J$7,0)+1) -> 10
A34: Efficiency Ratio | B34: =INDEX($A$8:$J$23,MATCH($A34,$A$8:$A$23,0),MATCH(B$26,$B$7:$J$7,0)+1) -> 1.84 | C34: =INDEX($A$8:$J$23,MATCH($A34,$A$8:$A$23,0),MATCH(C$26,$B$7:$J$7,0)+1) -> 1.94 | D34: =INDEX($A$8:$J$23,MATCH($A34,$A$8:$A$23,0),MATCH(D$26,$B$7:$J$7,0)+1) -> 1.874 | E34: =INDEX($A$8:$J$23,MATCH($A34,$A$8:$A$23,0),MATCH(E$26,$B$7:$J$7,0)+1) -> 1.88 | F34: =INDEX($A$8:$J$23,MATCH($A34,$A$8:$A$23,0),MATCH(F$26,$B$7:$J$7,0)+1) -> 2.1 | G34: =INDEX($A$8:$J$23,MATCH($A34,$A$8:$A$23,0),MATCH(G$26,$B$7:$J$7,0)+1) -> 2.375
A35: Assets | B35: =INDEX($A$8:$J$23,MATCH($A35,$A$8:$A$23,0),MATCH(B$26,$B$7:$J$7,0)+1) -> 240000 | C35: =INDEX($A$8:$J$23,MATCH($A35,$A$8:$A$23,0),MATCH(C$26,$B$7:$J$7,0)+1) -> 200000 | D35: =INDEX($A$8:$J$23,MATCH($A35,$A$8:$A$23,0),MATCH(D$26,$B$7:$J$7,0)+1) -> 295000 | E35: =INDEX($A$8:$J$23,MATCH($A35,$A$8:$A$23,0),MATCH(E$26,$B$7:$J$7,0)+1) -> 340000 | F35: =INDEX($A$8:$J$23,MATCH($A35,$A$8:$A$23,0),MATCH(F$26,$B$7:$J$7,0)+1) -> 387500 | G35: =INDEX($A$8:$J$23,MATCH($A35,$A$8:$A$23,0),MATCH(G$26,$B$7:$J$7,0)+1) -> 484375
A36: Loans | B36: =INDEX($A$8:$J$23,MATCH($A36,$A$8:$A$23,0),MATCH(B$26,$B$7:$J$7,0)+1) -> 129450 | C36: =INDEX($A$8:$J$23,MATCH($A36,$A$8:$A$23,0),MATCH(C$26,$B$7:$J$7,0)+1) -> 169382.5 | D36: =INDEX($A$8:$J$23,MATCH($A36,$A$8:$A$23,0),MATCH(D$26,$B$7:$J$7,0)+1) -> 176450 | E36: =INDEX($A$8:$J$23,MATCH($A36,$A$8:$A$23,0),MATCH(E$26,$B$7:$J$7,0)+1) -> 160492 | F36: =INDEX($A$8:$J$23,MATCH($A36,$A$8:$A$23,0),MATCH(F$26,$B$7:$J$7,0)+1) -> 200615 | G36: =INDEX($A$8:$J$23,MATCH($A36,$A$8:$A$23,0),MATCH(G$26,$B$7:$J$7,0)+1) -> 250768.75
A37: Core Deposits | B37: =INDEX($A$8:$J$23,MATCH($A37,$A$8:$A$23,0),MATCH(B$26,$B$7:$J$7,0)+1) -> 154465.5 | C37: =INDEX($A$8:$J$23,MATCH($A37,$A$8:$A$23,0),MATCH(C$26,$B$7:$J$7,0)+1) -> 137450 | D37: =INDEX($A$8:$J$23,MATCH($A37,$A$8:$A$23,0),MATCH(D$26,$B$7:$J$7,0)+1) -> 164575 | E37: =INDEX($A$8:$J$23,MATCH($A37,$A$8:$A$23,0),MATCH(E$26,$B$7:$J$7,0)+1) -> 152959 | F37: =INDEX($A$8:$J$23,MATCH($A37,$A$8:$A$23,0),MATCH(F$26,$B$7:$J$7,0)+1) -> 147959 | G37: =INDEX($A$8:$J$23,MATCH($A37,$A$8:$A$23,0),MATCH(G$26,$B$7:$J$7,0)+1) -> 153561.5
A38: Stockholder's Equity | B38: =INDEX($A$8:$J$23,MATCH($A38,$A$8:$A$23,0),MATCH(B$26,$B$7:$J$7,0)+1) -> 15770 | C38: =INDEX($A$8:$J$23,MATCH($A38,$A$8:$A$23,0),MATCH(C$26,$B$7:$J$7,0)+1) -> 16350 | D38: =INDEX($A$8:$J$23,MATCH($A38,$A$8:$A$23,0),MATCH(D$26,$B$7:$J$7,0)+1) -> 16935 | E38: =INDEX($A$8:$J$23,MATCH($A38,$A$8:$A$23,0),MATCH(E$26,$B$7:$J$7,0)+1) -> 17450 | F38: =INDEX($A$8:$J$23,MATCH($A38,$A$8:$A$23,0),MATCH(F$26,$B$7:$J$7,0)+1) -> 17950 | G38: =INDEX($A$8:$J$23,MATCH($A38,$A$8:$A$23,0),MATCH(G$26,$B$7:$J$7,0)+1) -> 18450
... A42: Net Charge Offs / Average Total Loans | B42: =INDEX($A$8:$J$23,MATCH($A42,$A$8:$A$23,0),MATCH(B$26,$B$7:$J$7,0)+1) -> 0.6 | C42: =INDEX($A$8:$J$23,MATCH($A42,$A$8:$A$23,0),MATCH(C$26,$B$7:$J$7,0)+1) -> 0.6 | D42: =INDEX($A$8:$J$23,MATCH($A42,$A$8:$A$23,0),MATCH(D$26,$B$7:$J$7,0)+1) -> 2.5 | E42: =INDEX($A$8:$J$23,MATCH($A42,$A$8:$A$23,0),MATCH(E$26,$B$7:$J$7,0)+1) -> 2.4 | F42: =INDEX($A$8:$J$23,MATCH($A42,$A$8:$A$23,0),MATCH(F$26,$B$7:$J$7,0)+1) -> 2.3 | G42: =INDEX($A$8:$J$23,MATCH($A42,$A$8:$A$23,0),MATCH(G$26,$B$7:$J$7,0)+1) -> 2.6
A45: Hires and Terminations | B45: ="FY "&IF(RIGHT(C45,2)-1<10,"0"&RIGHT(C45,2)-1,RIGHT(C45,2)-1) -> FY 12 | C45: ="FY "&IF(RIGHT(D45,2)-1<10,"0"&RIGHT(D45,2)-1,RIGHT(D45,2)-1) -> FY 13 | D45: =B26 -> FY 14 | E45: =C26 -> FY 15 | F45: =D26 -> FY 16 | G45: =E26 -> FY 17 | H45: =F26 -> FY 18 | I45: =G26 -> FY 19
A46: New Hires | B46: =SUMPRODUCT((Hires!$A$2:$A$10=$A46)*(Hires!$B$2:$B$10=$A$7)*(Hires!$C$1:$M$1=B$45)*(Hires!$C$2:$M$10)) -> 612 | C46: =SUMPRODUCT((Hires!$A$2:$A$10=$A46)*(Hires!$B$2:$B$10=$A$7)*(Hires!$C$1:$M$1=C$45)*(Hires!$C$2:$M$10)) -> 714 | D46: =SUMPRODUCT((Hires!$A$2:$A$10=$A46)*(Hires!$B$2:$B$10=$A$7)*(Hires!$C$1:$M$1=D$45)*(Hires!$C$2:$M$10)) -> 332 | E46: =SUMPRODUCT((Hires!$A$2:$A$10=$A46)*(Hires!$B$2:$B$10=$A$7)*(Hires!$C$1:$M$1=E$45)*(Hires!$C$2:$M$10)) -> 235 | F46: =SUMPRODUCT((Hires!$A$2:$A$10=$A46)*(Hires!$B$2:$B$10=$A$7)*(Hires!$C$1:$M$1=F$45)*(Hires!$C$2:$M$10)) -> 519 | G46: =SUMPRODUCT((Hires!$A$2:$A$10=$A46)*(Hires!$B$2:$B$10=$A$7)*(Hires!$C$1:$M$1=G$45)*(Hires!$C$2:$M$10)) -> 412 | H46: =SUMPRODUCT((Hires!$A$2:$A$10=$A46)*(Hires!$B$2:$B$10=$A$7)*(Hires!$C$1:$M$1=H$45)*(Hires!$C$2:$M$10)) -> 1020 | I46: =SUMPRODUCT((Hires!$A$2:$A$10=$A46)*(Hires!$B$2:$B$10=$A$7)*(Hires!$C$1:$M$1=I$45)*(Hires!$C$2:$M$10)) -> 1122
A47: Termination | B47: =SUMPRODUCT((Hires!$A$2:$A$10=$A47)*(Hires!$B$2:$B$10=$A$7)*(Hires!$C$1:$M$1=B$45)*(Hires!$C$2:$M$10)) -> -816 | C47: =SUMPRODUCT((Hires!$A$2:$A$10=$A47)*(Hires!$B$2:$B$10=$A$7)*(Hires!$C$1:$M$1=C$45)*(Hires!$C$2:$M$10)) -> -301 | D47: =SUMPRODUCT((Hires!$A$2:$A$10=$A47)*(Hires!$B$2:$B$10=$A$7)*(Hires!$C$1:$M$1=D$45)*(Hires!$C$2:$M$10)) -> -301 | E47: =SUMPRODUCT((Hires!$A$2:$A$10=$A47)*(Hires!$B$2:$B$10=$A$7)*(Hires!$C$1:$M$1=E$45)*(Hires!$C$2:$M$10)) -> -204 | F47: =SUMPRODUCT((Hires!$A$2:$A$10=$A47)*(Hires!$B$2:$B$10=$A$7)*(Hires!$C$1:$M$1=F$45)*(Hires!$C$2:$M$10)) -> -354 | G47: =SUMPRODUCT((Hires!$A$2:$A$10=$A47)*(Hires!$B$2:$B$10=$A$7)*(Hires!$C$1:$M$1=G$45)*(Hires!$C$2:$M$10)) -> -204 | H47: =SUMPRODUCT((Hires!$A$2:$A$10=$A47)*(Hires!$B$2:$B$10=$A$7)*(Hires!$C$1:$M$1=H$45)*(Hires!$C$2:$M$10)) -> -612 | I47: =SUMPRODUCT((Hires!$A$2:$A$10=$A47)*(Hires!$B$2:$B$10=$A$7)*(Hires!$C$1:$M$1=I$45)*(Hires!$C$2:$M$10)) -> -102
A50: Other Metrics | B50: Current Mth
A51: Interest Income | B51: =SUMPRODUCT((Other!$A$2:$A$40=$A$7)*(Other!$B$2:$B$40=$A51)*(Other!$C$2:$C$40)) -> 87.083333
A52: Funds Mgt Income | B52: =SUMPRODUCT((Other!$A$2:$A$40=$A$7)*(Other!$B$2:$B$40=$A52)*(Other!$C$2:$C$40)) -> 174.16667
A53: Insurance Income | B53: =SUMPRODUCT((Other!$A$2:$A$40=$A$7)*(Other!$B$2:$B$40=$A53)*(Other!$C$2:$C$40)) -> 130.625
A54: Other Bank Income | B54: =SUMPRODUCT((Other!$A$2:$A$40=$A$7)*(Other!$B$2:$B$40=$A54)*(Other!$C$2:$C$40)) -> 43.541667
A55: Net Income | B55: =SUMPRODUCT((Other!$A$2:$A$40=$A$7)*(Other!$B$2:$B$40=$A55)*(Other!$C$2:$C$40)) -> 435.41667
...

Sheet Check
B2: =Calcs!$A$7 -> Scotland | C2: =Calcs!B7 -> FY 12 | D2: =Calcs!C7 -> FY 13 | E2: =Calcs!D7 -> FY 14 | F2: =Calcs!E7 -> FY 15 | G2: =Calcs!F7 -> FY 16 | H2: =Calcs!G7 -> FY 17 | I2: =Calcs!H7 -> FY 18 | J2: =Calcs!I7 -> FY 19 | K2: =Calcs!J7 -> FY 20 | M2: Check
B3: Net Income | C3: =SUMIFS(Data!C$2:C$69,Data!$B$2:$B$69,$B3,Data!$A$2:$A$69,$B$2) -> 3330 | D3: =SUMIFS(Data!D$2:D$69,Data!$B$2:$B$69,$B3,Data!$A$2:$A$69,$B$2) -> 3685.5 | E3: =SUMIFS(Data!E$2:E$69,Data!$B$2:$B$69,$B3,Data!$A$2:$A$69,$B$2) -> 3818 | F3: =SUMIFS(Data!F$2:F$69,Data!$B$2:$B$69,$B3,Data!$A$2:$A$69,$B$2) -> 4464 | G3: =SUMIFS(Data!G$2:G$69,Data!$B$2:$B$69,$B3,Data!$A$2:$A$69,$B$2) -> 4794 | H3: =SUMIFS(Data!H$2:H$69,Data!$B$2:$B$69,$B3,Data!$A$2:$A$69,$B$2) -> 5225 | I3: =SUMIFS(Data!I$2:I$69,Data!$B$2:$B$69,$B3,Data!$A$2:$A$69,$B$2) -> 5376 | J3: =SUMIFS(Data!J$2:J$69,Data!$B$2:$B$69,$B3,Data!$A$2:$A$69,$B$2) -> 4794 | K3: =SUMIFS(Data!K$2:K$69,Data!$B$2:$B$69,$B3,Data!$A$2:$A$69,$B$2) -> 5225
B4: Revenue | C4: =SUMIFS(Data!C$2:C$69,Data!$B$2:$B$69,$B4,Data!$A$2:$A$69,$B$2) -> 13005 | D4: =SUMIFS(Data!D$2:D$69,Data!$B$2:$B$69,$B4,Data!$A$2:$A$69,$B$2) -> 15273.895 | E4: =SUMIFS(Data!E$2:E$69,Data!$B$2:$B$69,$B4,Data!$A$2:$A$69,$B$2) -> 15875.06 | F4: =SUMIFS(Data!F$2:F$69,Data!$B$2:$B$69,$B4,Data!$A$2:$A$69,$B$2) -> 16590.27 | G4: =SUMIFS(Data!G$2:G$69,Data!$B$2:$B$69,$B4,Data!$A$2:$A$69,$B$2) -> 18318.72 | H4: =SUMIFS(Data!H$2:H$69,Data!$B$2:$B$69,$B4,Data!$A$2:$A$69,$B$2) -> 19006.65 | I4: =SUMIFS(Data!I$2:I$69,Data!$B$2:$B$69,$B4,Data!$A$2:$A$69,$B$2) -> 24008.4 | J4: =SUMIFS(Data!J$2:J$69,Data!$B$2:$B$69,$B4,Data!$A$2:$A$69,$B$2) -> 18318.72 | K4: =SUMIFS(Data!K$2:K$69,Data!$B$2:$B$69,$B4,Data!$A$2:$A$69,$B$2) -> 19006.65
B5: Diluted Earnings Per Share | C5: =SUMIFS(Data!C$2:C$69,Data!$B$2:$B$69,$B5,Data!$A$2:$A$69,$B$2) -> 2.1 | D5: =SUMIFS(Data!D$2:D$69,Data!$B$2:$B$69,$B5,Data!$A$2:$A$69,$B$2) -> 2.2 | E5: =SUMIFS(Data!E$2:E$69,Data!$B$2:$B$69,$B5,Data!$A$2:$A$69,$B$2) -> 2.35 | F5: =SUMIFS(Data!F$2:F$69,Data!$B$2:$B$69,$B5,Data!$A$2:$A$69,$B$2) -> 2.4 | G5: =SUMIFS(Data!G$2:G$69,Data!$B$2:$B$69,$B5,Data!$A$2:$A$69,$B$2) -> 2.45 | H5: =SUMIFS(Data!H$2:H$69,Data!$B$2:$B$69,$B5,Data!$A$2:$A$69,$B$2) -> 3.2 | I5: =SUMIFS(Data!I$2:I$69,Data!$B$2:$B$69,$B5,Data!$A$2:$A$69,$B$2) -> 4.5 | J5: =SUMIFS(Data!J$2:J$69,Data!$B$2:$B$69,$B5,Data!$A$2:$A$69,$B$2) -> 5.625 | K5: =SUMIFS(Data!K$2:K$69,Data!$B$2:$B$69,$B5,Data!$A$2:$A$69,$B$2) -> 3.6
B6: Dividends Per Share | C6: =SUMIFS(Data!C$2:C$69,Data!$B$2:$B$69,$B6,Data!$A$2:$A$69,$B$2) -> 0.67 | D6: =SUMIFS(Data!D$2:D$69,Data!$B$2:$B$69,$B6,Data!$A$2:$A$69,$B$2) -> 0.77 | E6: =SUMIFS(Data!E$2:E$69,Data!$B$2:$B$69,$B6,Data!$A$2:$A$69,$B$2) -> 0.87 | F6: =SUMIFS(Data!F$2:F$69,Data!$B$2:$B$69,$B6,Data!$A$2:$A$69,$B$2) -> 0.97 | G6: =SUMIFS(Data!G$2:G$69,Data!$B$2:$B$69,$B6,Data!$A$2:$A$69,$B$2) -> 0.67 | H6: =SUMIFS(Data!H$2:H$69,Data!$B$2:$B$69,$B6,Data!$A$2:$A$69,$B$2) -> 0.77 | I6: =SUMIFS(Data!I$2:I$69,Data!$B$2:$B$69,$B6,Data!$A$2:$A$69,$B$2) -> 0.87 | J6: =SUMIFS(Data!J$2:J$69,Data!$B$2:$B$69,$B6,Data!$A$2:$A$69,$B$2) -> 0.97 | K6: =SUMIFS(Data!K$2:K$69,Data!$B$2:$B$69,$B6,Data!$A$2:$A$69,$B$2) -> 1.07
B7: Return on Assets | C7: =SUMIFS(Data!C$2:C$69,Data!$B$2:$B$69,$B7,Data!$A$2:$A$69,$B$2) -> 1.6 | D7: =SUMIFS(Data!D$2:D$69,Data!$B$2:$B$69,$B7,Data!$A$2:$A$69,$B$2) -> 1.7 | E7: =SUMIFS(Data!E$2:E$69,Data!$B$2:$B$69,$B7,Data!$A$2:$A$69,$B$2) -> 1.6 | F7: =SUMIFS(Data!F$2:F$69,Data!$B$2:$B$69,$B7,Data!$A$2:$A$69,$B$2) -> 1.5 | G7: =SUMIFS(Data!G$2:G$69,Data!$B$2:$B$69,$B7,Data!$A$2:$A$69,$B$2) -> 3.5 | H7: =SUMIFS(Data!H$2:H$69,Data!$B$2:$B$69,$B7,Data!$A$2:$A$69,$B$2) -> 3.6 | I7: =SUMIFS(Data!I$2:I$69,Data!$B$2:$B$69,$B7,Data!$A$2:$A$69,$B$2) -> 4.25 | J7: =SUMIFS(Data!J$2:J$69,Data!$B$2:$B$69,$B7,Data!$A$2:$A$69,$B$2) -> 5.0625 | K7: =SUMIFS(Data!K$2:K$69,Data!$B$2:$B$69,$B7,Data!$A$2:$A$69,$B$2) -> 6.078125
B8: Return on Equity | C8: =SUMIFS(Data!C$2:C$69,Data!$B$2:$B$69,$B8,Data!$A$2:$A$69,$B$2) -> 22.4 | D8: =SUMIFS(Data!D$2:D$69,Data!$B$2:$B$69,$B8,Data!$A$2:$A$69,$B$2) -> 22.5 | E8: =SUMIFS(Data!E$2:E$69,Data!$B$2:$B$69,$B8,Data!$A$2:$A$69,$B$2) -> 25.8 | F8: =SUMIFS(Data!F$2:F$69,Data!$B$2:$B$69,$B8,Data!$A$2:$A$69,$B$2) -> 24.7 | G8: =SUMIFS(Data!G$2:G$69,Data!$B$2:$B$69,$B8,Data!$A$2:$A$69,$B$2) -> 28.6 | H8: =SUMIFS(Data!H$2:H$69,Data!$B$2:$B$69,$B8,Data!$A$2:$A$69,$B$2) -> 29.6 | I8: =SUMIFS(Data!I$2:I$69,Data!$B$2:$B$69,$B8,Data!$A$2:$A$69,$B$2) -> 31.75 | J8: =SUMIFS(Data!J$2:J$69,Data!$B$2:$B$69,$B8,Data!$A$2:$A$69,$B$2) -> 26.6875 | K8: =SUMIFS(Data!K$2:K$69,Data!$B$2:$B$69,$B8,Data!$A$2:$A$69,$B$2) -> 23.859375
B9: Net Interest Margin | C9: =SUMIFS(Data!C$2:C$69,Data!$B$2:$B$69,$B9,Data!$A$2:$A$69,$B$2) -> 6.5 | D9: =SUMIFS(Data!D$2:D$69,Data!$B$2:$B$69,$B9,Data!$A$2:$A$69,$B$2) -> 6.6 | E9: =SUMIFS(Data!E$2:E$69,Data!$B$2:$B$69,$B9,Data!$A$2:$A$69,$B$2) -> 7.3 | F9: =SUMIFS(Data!F$2:F$69,Data!$B$2:$B$69,$B9,Data!$A$2:$A$69,$B$2) -> 7.3 | G9: =SUMIFS(Data!G$2:G$69,Data!$B$2:$B$69,$B9,Data!$A$2:$A$69,$B$2) -> 9.4 | H9: =SUMIFS(Data!H$2:H$69,Data!$B$2:$B$69,$B9,Data!$A$2:$A$69,$B$2) -> 9.7 | I9: =SUMIFS(Data!I$2:I$69,Data!$B$2:$B$69,$B9,Data!$A$2:$A$69,$B$2) -> 9.875 | J9: =SUMIFS(Data!J$2:J$69,Data!$B$2:$B$69,$B9,Data!$A$2:$A$69,$B$2) -> 10 | K9: =SUMIFS(Data!K$2:K$69,Data!$B$2:$B$69,$B9,Data!$A$2:$A$69,$B$2) -> 9.7
B10: Efficiency Ratio | C10: =SUMIFS(Data!C$2:C$69,Data!$B$2:$B$69,$B10,Data!$A$2:$A$69,$B$2) -> 1.64 | D10: =SUMIFS(Data!D$2:D$69,Data!$B$2:$B$69,$B10,Data!$A$2:$A$69,$B$2) -> 1.74 | E10: =SUMIFS(Data!E$2:E$69,Data!$B$2:$B$69,$B10,Data!$A$2:$A$69,$B$2) -> 1.84 | F10: =SUMIFS(Data!F$2:F$69,Data!$B$2:$B$69,$B10,Data!$A$2:$A$69,$B$2) -> 1.94 | G10: =SUMIFS(Data!G$2:G$69,Data!$B$2:$B$69,$B10,Data!$A$2:$A$69,$B$2) -> 1.874 | H10: =SUMIFS(Data!H$2:H$69,Data!$B$2:$B$69,$B10,Data!$A$2:$A$69,$B$2) -> 1.88 | I10: =SUMIFS(Data!I$2:I$69,Data!$B$2:$B$69,$B10,Data!$A$2:$A$69,$B$2) -> 2.1 | J10: =SUMIFS(Data!J$2:J$69,Data!$B$2:$B$69,$B10,Data!$A$2:$A$69,$B$2) -> 2.375 | K10: =SUMIFS(Data!K$2:K$69,Data!$B$2:$B$69,$B10,Data!$A$2:$A$69,$B$2) -> 2.21875
B11: Assets | C11: =SUMIFS(Data!C$2:C$69,Data!$B$2:$B$69,$B11,Data!$A$2:$A$69,$B$2) -> 270000 | D11: =SUMIFS(Data!D$2:D$69,Data!$B$2:$B$69,$B11,Data!$A$2:$A$69,$B$2) -> 270000.1 | E11: =SUMIFS(Data!E$2:E$69,Data!$B$2:$B$69,$B11,Data!$A$2:$A$69,$B$2) -> 240000 | F11: =SUMIFS(Data!F$2:F$69,Data!$B$2:$B$69,$B11,Data!$A$2:$A$69,$B$2) -> 200000 | G11: =SUMIFS(Data!G$2:G$69,Data!$B$2:$B$69,$B11,Data!$A$2:$A$69,$B$2) -> 295000 | H11: =SUMIFS(Data!H$2:H$69,Data!$B$2:$B$69,$B11,Data!$A$2:$A$69,$B$2) -> 340000 | I11: =SUMIFS(Data!I$2:I$69,Data!$B$2:$B$69,$B11,Data!$A$2:$A$69,$B$2) -> 387500 | J11: =SUMIFS(Data!J$2:J$69,Data!$B$2:$B$69,$B11,Data!$A$2:$A$69,$B$2) -> 484375 | K11: =SUMIFS(Data!K$2:K$69,Data!$B$2:$B$69,$B11,Data!$A$2:$A$69,$B$2) -> 605468.75
B12: Loans | C12: =SUMIFS(Data!C$2:C$69,Data!$B$2:$B$69,$B12,Data!$A$2:$A$69,$B$2) -> 157961.5 | D12: =SUMIFS(Data!D$2:D$69,Data!$B$2:$B$69,$B12,Data!$A$2:$A$69,$B$2) -> 157961.6 | E12: =SUMIFS(Data!E$2:E$69,Data!$B$2:$B$69,$B12,Data!$A$2:$A$69,$B$2) -> 129450 | F12: =SUMIFS(Data!F$2:F$69,Data!$B$2:$B$69,$B12,Data!$A$2:$A$69,$B$2) -> 169382.5 | G12: =SUMIFS(Data!G$2:G$69,Data!$B$2:$B$69,$B12,Data!$A$2:$A$69,$B$2) -> 176450 | H12: =SUMIFS(Data!H$2:H$69,Data!$B$2:$B$69,$B12,Data!$A$2:$A$69,$B$2) -> 160492 | I12: =SUMIFS(Data!I$2:I$69,Data!$B$2:$B$69,$B12,Data!$A$2:$A$69,$B$2) -> 200615 | J12: =SUMIFS(Data!J$2:J$69,Data!$B$2:$B$69,$B12,Data!$A$2:$A$69,$B$2) -> 250768.75 | K12: =SUMIFS(Data!K$2:K$69,Data!$B$2:$B$69,$B12,Data!$A$2:$A$69,$B$2) -> 313460.94
B13: Core Deposits | C13: =SUMIFS(Data!C$2:C$69,Data!$B$2:$B$69,$B13,Data!$A$2:$A$69,$B$2) -> 146825.5 | D13: =SUMIFS(Data!D$2:D$69,Data!$B$2:$B$69,$B13,Data!$A$2:$A$69,$B$2) -> 146825.6 | E13: =SUMIFS(Data!E$2:E$69,Data!$B$2:$B$69,$B13,Data!$A$2:$A$69,$B$2) -> 154465.5 | F13: =SUMIFS(Data!F$2:F$69,Data!$B$2:$B$69,$B13,Data!$A$2:$A$69,$B$2) -> 137450 | G13: =SUMIFS(Data!G$2:G$69,Data!$B$2:$B$69,$B13,Data!$A$2:$A$69,$B$2) -> 164575 | H13: =SUMIFS(Data!H$2:H$69,Data!$B$2:$B$69,$B13,Data!$A$2:$A$69,$B$2) -> 152959 | I13: =SUMIFS(Data!I$2:I$69,Data!$B$2:$B$69,$B13,Data!$A$2:$A$69,$B$2) -> 147959 | J13: =SUMIFS(Data!J$2:J$69,Data!$B$2:$B$69,$B13,Data!$A$2:$A$69,$B$2) -> 153561.5 | K13: =SUMIFS(Data!K$2:K$69,Data!$B$2:$B$69,$B13,Data!$A$2:$A$69,$B$2) -> 147959
B14: Stockholder's Equity | C14: =SUMIFS(Data!C$2:C$69,Data!$B$2:$B$69,$B14,Data!$A$2:$A$69,$B$2) -> 14375 | D14: =SUMIFS(Data!D$2:D$69,Data!$B$2:$B$69,$B14,Data!$A$2:$A$69,$B$2) -> 14375.1 | E14: =SUMIFS(Data!E$2:E$69,Data!$B$2:$B$69,$B14,Data!$A$2:$A$69,$B$2) -> 15770 | F14: =SUMIFS(Data!F$2:F$69,Data!$B$2:$B$69,$B14,Data!$A$2:$A$69,$B$2) -> 16350 | G14: =SUMIFS(Data!G$2:G$69,Data!$B$2:$B$69,$B14,Data!$A$2:$A$69,$B$2) -> 16935 | H14: =SUMIFS(Data!H$2:H$69,Data!$B$2:$B$69,$B14,Data!$A$2:$A$69,$B$2) -> 17450 | I14: =SUMIFS(Data!I$2:I$69,Data!$B$2:$B$69,$B14,Data!$A$2:$A$69,$B$2) -> 17950 | J14: =SUMIFS(Data!J$2:J$69,Data!$B$2:$B$69,$B14,Data!$A$2:$A$69,$B$2) -> 18450 | K14: =SUMIFS(Data!K$2:K$69,Data!$B$2:$B$69,$B14,Data!$A$2:$A$69,$B$2) -> 18950
... B18: Net Charge Offs / Average Total Loans | C18: =SUMIFS(Data!C$2:C$69,Data!$B$2:$B$69,$B18,Data!$A$2:$A$69,$B$2) -> 0.7 | D18: =SUMIFS(Data!D$2:D$69,Data!$B$2:$B$69,$B18,Data!$A$2:$A$69,$B$2) -> 0.8 | E18: =SUMIFS(Data!E$2:E$69,Data!$B$2:$B$69,$B18,Data!$A$2:$A$69,$B$2) -> 0.6 | F18: =SUMIFS(Data!F$2:F$69,Data!$B$2:$B$69,$B18,Data!$A$2:$A$69,$B$2) -> 0.6 | G18: =SUMIFS(Data!G$2:G$69,Data!$B$2:$B$69,$B18,Data!$A$2:$A$69,$B$2) -> 2.5 | H18: =SUMIFS(Data!H$2:H$69,Data!$B$2:$B$69,$B18,Data!$A$2:$A$69,$B$2) -> 2.4 | I18: =SUMIFS(Data!I$2:I$69,Data!$B$2:$B$69,$B18,Data!$A$2:$A$69,$B$2) -> 2.3 | J18: =SUMIFS(Data!J$2:J$69,Data!$B$2:$B$69,$B18,Data!$A$2:$A$69,$B$2) -> 2.6 | K18: =SUMIFS(Data!K$2:K$69,Data!$B$2:$B$69,$B18,Data!$A$2:$A$69,$B$2) -> 2.5
B20: Check | C20: =SUM(C3:C19) -> 605537.66 | D20: =SUM(D3:D19) -> 608163.45 | E20: =SUM(E3:E19) -> 559423.97 | F20: =SUM(F3:F19) -> 544281.23 | G20: =SUM(G3:G19) -> 676132.71 | H20: =SUM(H3:H19) -> 695195.2 | I20: =SUM(I3:I19) -> 783475.55 | J20: =SUM(J3:J19) -> 930332.29 | K20: =SUM(K3:K19) -> 1110130.6
B22: Total Check | C22: =C20-SUM(Calcs!B8:B24) -> 0 | D22: =D20-SUM(Calcs!C8:C24) -> 0 | E22: =E20-SUM(Calcs!D8:D24) -> 0 | F22: =F20-SUM(Calcs!E8:E24) -> 0 | G22: =G20-SUM(Calcs!F8:F24) -> 0 | H22: =H20-SUM(Calcs!G8:G24) -> 0 | I22: =I20-SUM(Calcs!H8:H24) -> 0 | J22: =J20-SUM(Calcs!I8:I24) -> 0 | K22: =K20-SUM(Calcs!J8:J24) -> 0 | M22: =SUM(C22:L22) -> 0
B25: Metric | C25: CM Data | D25: Check | M25: Check
B26: Interest Income | C26: =SUMIFS(Other!$C$2:$C$41,Other!$A$2:$A$41,$B$2,Other!$B$2:$B$41,$B26) -> 87.083333 | D26: =C26-Calcs!B51 -> 0
B27: Funds Mgt Income | C27: =SUMIFS(Other!$C$2:$C$41,Other!$A$2:$A$41,$B$2,Other!$B$2:$B$41,$B27) -> 174.16667 | D27: =C27-Calcs!B52 -> 0
B28: Insurance Income | C28: =SUMIFS(Other!$C$2:$C$41,Other!$A$2:$A$41,$B$2,Other!$B$2:$B$41,$B28) -> 130.625 | D28: =C28-Calcs!B53 -> 0
B29: Other Bank Income | C29: =SUMIFS(Other!$C$2:$C$41,Other!$A$2:$A$41,$B$2,Other!$B$2:$B$41,$B29) -> 43.541667 | D29: =C29-Calcs!B54 -> 0
B30: Net Income | C30: =SUMIFS(Other!$C$2:$C$41,Other!$A$2:$A$41,$B$2,Other!$B$2:$B$41,$B30) -> 435.41667 | D30: =C30-Calcs!B55 -> 0
B31: Operational Expenses | C31: =SUMIFS(Other!$C$2:$C$41,Other!$A$2:$A$41,$B$2,Other!$B$2:$B$41,$B31) -> 217.70833 | D31: =C31-Calcs!B56 -> 0
B32: Loan Imparement Expenses | C32: =SUMIFS(Other!$C$2:$C$41,Other!$A$2:$A$41,$B$2,Other!$B$2:$B$41,$B32) -> 54.427083 | D32: =C32-Calcs!B57 -> 0
B33: Net Expenses | C33: =SUMIFS(Other!$C$2:$C$41,Other!$A$2:$A$41,$B$2,Other!$B$2:$B$41,$B33) -> 272.13542 | D33: =C33-Calcs!B58 -> 0
B34: Net Profit | C34: =SUMIFS(Other!$C$2:$C$41,Other!$A$2:$A$41,$B$2,Other!$B$2:$B$41,$B34) -> 163.28125 | D34: =C34-Calcs!B59 -> 0
B36: Check | D36: =SUM(D26:D35) -> 0 | M36: =SUM(C36:L36) -> 0
B38: Hires and Terminations | C38: =Calcs!B45 -> FY 12 | D38: =Calcs!C45 -> FY 13 | E38: =Calcs!D45 -> FY 14 | F38: =Calcs!E45 -> FY 15 | G38: =Calcs!F45 -> FY 16 | H38: =Calcs!G45 -> FY 17 | I38: =Calcs!H45 -> FY 18 | J38: =Calcs!I45 -> FY 19 | M38: Check
B39: New Hires | C39: =SUMPRODUCT((Hires!$A$2:$A$10=$B39)*(Hires!$B$2:$B$10=$B$2)*(Hires!$C$1:$M$1=C$38)*(Hires!$C$2:$M$10)) -> 612 | D39: =SUMPRODUCT((Hires!$A$2:$A$10=$B39)*(Hires!$B$2:$B$10=$B$2)*(Hires!$C$1:$M$1=D$38)*(Hires!$C$2:$M$10)) -> 714 | E39: =SUMPRODUCT((Hires!$A$2:$A$10=$B39)*(Hires!$B$2:$B$10=$B$2)*(Hires!$C$1:$M$1=E$38)*(Hires!$C$2:$M$10)) -> 332 | F39: =SUMPRODUCT((Hires!$A$2:$A$10=$B39)*(Hires!$B$2:$B$10=$B$2)*(Hires!$C$1:$M$1=F$38)*(Hires!$C$2:$M$10)) -> 235 | G39: =SUMPRODUCT((Hires!$A$2:$A$10=$B39)*(Hires!$B$2:$B$10=$B$2)*(Hires!$C$1:$M$1=G$38)*(Hires!$C$2:$M$10)) -> 519 | H39: =SUMPRODUCT((Hires!$A$2:$A$10=$B39)*(Hires!$B$2:$B$10=$B$2)*(Hires!$C$1:$M$1=H$38)*(Hires!$C$2:$M$10)) -> 412 | I39: =SUMPRODUCT((Hires!$A$2:$A$10=$B39)*(Hires!$B$2:$B$10=$B$2)*(Hires!$C$1:$M$1=I$38)*(Hires!$C$2:$M$10)) -> 1020 | J39: =SUMPRODUCT((Hires!$A$2:$A$10=$B39)*(Hires!$B$2:$B$10=$B$2)*(Hires!$C$1:$M$1=J$38)*(Hires!$C$2:$M$10)) -> 1122
B40: Termination | C40: =SUMPRODUCT((Hires!$A$2:$A$10=$B40)*(Hires!$B$2:$B$10=$B$2)*(Hires!$C$1:$M$1=C$38)*(Hires!$C$2:$M$10)) -> -816 | D40: =SUMPRODUCT((Hires!$A$2:$A$10=$B40)*(Hires!$B$2:$B$10=$B$2)*(Hires!$C$1:$M$1=D$38)*(Hires!$C$2:$M$10)) -> -301 | E40: =SUMPRODUCT((Hires!$A$2:$A$10=$B40)*(Hires!$B$2:$B$10=$B$2)*(Hires!$C$1:$M$1=E$38)*(Hires!$C$2:$M$10)) -> -301 | F40: =SUMPRODUCT((Hires!$A$2:$A$10=$B40)*(Hires!$B$2:$B$10=$B$2)*(Hires!$C$1:$M$1=F$38)*(Hires!$C$2:$M$10)) -> -204 | G40: =SUMPRODUCT((Hires!$A$2:$A$10=$B40)*(Hires!$B$2:$B$10=$B$2)*(Hires!$C$1:$M$1=G$38)*(Hires!$C$2:$M$10)) -> -354 | H40: =SUMPRODUCT((Hires!$A$2:$A$10=$B40)*(Hires!$B$2:$B$10=$B$2)*(Hires!$C$1:$M$1=H$38)*(Hires!$C$2:$M$10)) -> -204 | I40: =SUMPRODUCT((Hires!$A$2:$A$10=$B40)*(Hires!$B$2:$B$10=$B$2)*(Hires!$C$1:$M$1=I$38)*(Hires!$C$2:$M$10)) -> -612 | J40: =SUMPRODUCT((Hires!$A$2:$A$10=$B40)*(Hires!$B$2:$B$10=$B$2)*(Hires!$C$1:$M$1=J$38)*(Hires!$C$2:$M$10)) -> -102
