Workbook
Name AP: DashBoard!$AT$23:$BC$36
Name APpercent: DashBoard!$AT$48:$AZ$60
Name DMC_AP: DashBoard!A$66:P$78
Name DMC_RN: DashBoard!$AT$83:$BF$95
Name mySortCriteria: DashBoard!$AU$117
Name RN: DashBoard!$AT$3:$BE$15

Sheet DashBoard
B2: =CONCATENATE(parameters!C2," Dashboard",parameters!C3) -> Sample Travel Site Dashboard | AY2: Based on Budgetd | BA2: Normalized | BF2: 1 | BJ2: 2 | BK2: 3 | BL2: 4 | BM2: 5 | BN2: 6 | BO2: 7 | BP2: 8 | BQ2: 9 | BR2: 10 | BS2: 11 | BT2: 12 | BU2: 13 | BV2: 14 | BW2: 15 | BX2: 16 | BY2: 17 | BZ2: 18 | CA2: 19 | CB2: 20
AT3: RN | AU3: Actual | AV3: Budgeted | AW3: Last Year | AX3: YTD | AY3: Bad | AZ3: Ok | BA3: Last Year | BB3: RN | BC3: Total | BD3: Bad | BE3: Ok
AK4: Choose Month | AT4: 44652 | AU4: 25 | AV4: 50 | AW4: 31 | AX4: =AU4 -> 25 | AY4: =ROUND(AV4*parameters!$C$6,0) -> 25 | AZ4: =ROUND(AV4*parameters!$C$7,0) -> 40 | BA4: =ROUND((AW4/AV4)*20,0) -> 12 | BB4: =ROUND((AU4/AV4)*20,0) -> 10 | BC4: 20 | BD4: =ROUND((AY4/AV4)*20,0) -> 10 | BE4: =ROUND((AZ4/AV4)*20,0) -> 16 | BF4: =IF(BF$2=$BA4,IF(BF$2<=$BB4,parameters!$H$7,parameters!$I$7),IF(BF$2<=$BB4,parameters!$G$7,"")) -> ─ | BJ4: =IF(BJ$2=$BA4,IF(BJ$2<=$BB4,parameters!$H$7,parameters!$I$7),IF(BJ$2<=$BB4,parameters!$G$7,"")) -> ─ | BK4: =IF(BK$2=$BA4,IF(BK$2<=$BB4,parameters!$H$7,parameters!$I$7),IF(BK$2<=$BB4,parameters!$G$7,"")) -> ─ | BL4: =IF(BL$2=$BA4,IF(BL$2<=$BB4,parameters!$H$7,parameters!$I$7),IF(BL$2<=$BB4,parameters!$G$7,"")) -> ─ | BM4: =IF(BM$2=$BA4,IF(BM$2<=$BB4,parameters!$H$7,parameters!$I$7),IF(BM$2<=$BB4,parameters!$G$7,"")) -> ─ | BN4: =IF(BN$2=$BA4,IF(BN$2<=$BB4,parameters!$H$7,parameters!$I$7),IF(BN$2<=$BB4,parameters!$G$7,"")) -> ─ | BO4: =IF(BO$2=$BA4,IF(BO$2<=$BB4,parameters!$H$7,parameters!$I$7),IF(BO$2<=$BB4,parameters!$G$7,"")) -> ─ | BP4: =IF(BP$2=$BA4,IF(BP$2<=$BB4,parameters!$H$7,parameters!$I$7),IF(BP$2<=$BB4,parameters!$G$7,"")) -> ─ | BQ4: =IF(BQ$2=$BA4,IF(BQ$2<=$BB4,parameters!$H$7,parameters!$I$7),IF(BQ$2<=$BB4,parameters!$G$7,"")) -> ─ | ... CB4: =IF(CB$2=$BA4,IF(CB$2<=$BB4,parameters!$H$7,parameters!$I$7),IF(CB$2<=$BB4,parameters!$G$7,""))
AT5: 44682 | AU5: 37 | AV5: 50 | AW5: 29 | AX5: =IF(AU5=0,0,AX4+AU5) -> 62 | AY5: =ROUND(AV5*parameters!$C$6,0) -> 25 | AZ5: =ROUND(AV5*parameters!$C$7,0) -> 40 | BA5: =ROUND((AW5/AV5)*20,0) -> 12 | BB5: =ROUND((AU5/AV5)*20,0) -> 15 | BC5: 20 | BD5: =ROUND((AY5/AV5)*20,0) -> 10 | BE5: =ROUND((AZ5/AV5)*20,0) -> 16 | BF5: =IF(BF$2=$BA5,IF(BF$2<=$BB5,parameters!$H$7,parameters!$I$7),IF(BF$2<=$BB5,parameters!$G$7,"")) -> ─ | BJ5: =IF(BJ$2=$BA5,IF(BJ$2<=$BB5,parameters!$H$7,parameters!$I$7),IF(BJ$2<=$BB5,parameters!$G$7,"")) -> ─ | BK5: =IF(BK$2=$BA5,IF(BK$2<=$BB5,parameters!$H$7,parameters!$I$7),IF(BK$2<=$BB5,parameters!$G$7,"")) -> ─ | BL5: =IF(BL$2=$BA5,IF(BL$2<=$BB5,parameters!$H$7,parameters!$I$7),IF(BL$2<=$BB5,parameters!$G$7,"")) -> ─ | BM5: =IF(BM$2=$BA5,IF(BM$2<=$BB5,parameters!$H$7,parameters!$I$7),IF(BM$2<=$BB5,parameters!$G$7,"")) -> ─ | BN5: =IF(BN$2=$BA5,IF(BN$2<=$BB5,parameters!$H$7,parameters!$I$7),IF(BN$2<=$BB5,parameters!$G$7,"")) -> ─ | BO5: =IF(BO$2=$BA5,IF(BO$2<=$BB5,parameters!$H$7,parameters!$I$7),IF(BO$2<=$BB5,parameters!$G$7,"")) -> ─ | BP5: =IF(BP$2=$BA5,IF(BP$2<=$BB5,parameters!$H$7,parameters!$I$7),IF(BP$2<=$BB5,parameters!$G$7,"")) -> ─ | BQ5: =IF(BQ$2=$BA5,IF(BQ$2<=$BB5,parameters!$H$7,parameters!$I$7),IF(BQ$2<=$BB5,parameters!$G$7,"")) -> ─ | ... CB5: =IF(CB$2=$BA5,IF(CB$2<=$BB5,parameters!$H$7,parameters!$I$7),IF(CB$2<=$BB5,parameters!$G$7,""))
B6: KPI | C6: Room Night | F6: GOR | L6: A&P Spent | X6: A&P % | AD6: =CONCATENATE("We need ",ROUND((D12-C12)/(30-DAY(TODAY())),0)," RN per day to hit Target") -> We need 1 RN per day to hit Target | AT6: 44713 | AU6: 68 | AV6: 48 | AW6: 2 | AX6: =IF(AU6=0,0,AX5+AU6) -> 130 | AY6: =ROUND(AV6*parameters!$C$6,0) -> 24 | AZ6: =ROUND(AV6*parameters!$C$7,0) -> 38 | BA6: =ROUND((AW6/AV6)*20,0) -> 1 | BB6: =ROUND((AU6/AV6)*20,0) -> 28 | BC6: 20 | BD6: =ROUND((AY6/AV6)*20,0) -> 10 | BE6: =ROUND((AZ6/AV6)*20,0) -> 16 | BF6: =IF(BF$2=$BA6,IF(BF$2<=$BB6,parameters!$H$7,parameters!$I$7),IF(BF$2<=$BB6,parameters!$G$7,"")) -> ┼ | BJ6: =IF(BJ$2=$BA6,IF(BJ$2<=$BB6,parameters!$H$7,parameters!$I$7),IF(BJ$2<=$BB6,parameters!$G$7,"")) -> ─ | BK6: =IF(BK$2=$BA6,IF(BK$2<=$BB6,parameters!$H$7,parameters!$I$7),IF(BK$2<=$BB6,parameters!$G$7,"")) -> ─ | BL6: =IF(BL$2=$BA6,IF(BL$2<=$BB6,parameters!$H$7,parameters!$I$7),IF(BL$2<=$BB6,parameters!$G$7,"")) -> ─ | BM6: =IF(BM$2=$BA6,IF(BM$2<=$BB6,parameters!$H$7,parameters!$I$7),IF(BM$2<=$BB6,parameters!$G$7,"")) -> ─ | BN6: =IF(BN$2=$BA6,IF(BN$2<=$BB6,parameters!$H$7,parameters!$I$7),IF(BN$2<=$BB6,parameters!$G$7,"")) -> ─ | BO6: =IF(BO$2=$BA6,IF(BO$2<=$BB6,parameters!$H$7,parameters!$I$7),IF(BO$2<=$BB6,parameters!$G$7,"")) -> ─ | BP6: =IF(BP$2=$BA6,IF(BP$2<=$BB6,parameters!$H$7,parameters!$I$7),IF(BP$2<=$BB6,parameters!$G$7,"")) -> ─ | BQ6: =IF(BQ$2=$BA6,IF(BQ$2<=$BB6,parameters!$H$7,parameters!$I$7),IF(BQ$2<=$BB6,parameters!$G$7,"")) -> ─ | ... CB6: =IF(CB$2=$BA6,IF(CB$2<=$BB6,parameters!$H$7,parameters!$I$7),IF(CB$2<=$BB6,parameters!$G$7,"")) -> ─
C7: =C12 -> 37 | F7: =C12*parameters!C4 -> 9620 | L7: =INDEX(AP,AT17+1,6) -> 5248 | X7: =L7/F7 -> 0.54553015 | AD7: ="Sales " & TEXT(AU63,"0%;0%;0%;") & " "&IF(AU63>0,"Up from previous month", "Down from previous month") -> Sales 48% Up from previous month | AJ7: =IF(AU63>0,"Let's Celebrate !!!","Work Harder!") -> Let's Celebrate !!! | AT7: 44743 | AU7: 32 | AV7: 99 | AW7: 4 | AX7: =IF(AU7=0,0,AX6+AU7) -> 162 | AY7: =ROUND(AV7*parameters!$C$6,0) -> 50 | AZ7: =ROUND(AV7*parameters!$C$7,0) -> 79 | BA7: =ROUND((AW7/AV7)*20,0) -> 1 | BB7: =ROUND((AU7/AV7)*20,0) -> 6 | BC7: 20 | BD7: =ROUND((AY7/AV7)*20,0) -> 10 | BE7: =ROUND((AZ7/AV7)*20,0) -> 16 | BF7: =IF(BF$2=$BA7,IF(BF$2<=$BB7,parameters!$H$7,parameters!$I$7),IF(BF$2<=$BB7,parameters!$G$7,"")) -> ┼ | BJ7: =IF(BJ$2=$BA7,IF(BJ$2<=$BB7,parameters!$H$7,parameters!$I$7),IF(BJ$2<=$BB7,parameters!$G$7,"")) -> ─ | BK7: =IF(BK$2=$BA7,IF(BK$2<=$BB7,parameters!$H$7,parameters!$I$7),IF(BK$2<=$BB7,parameters!$G$7,"")) -> ─ | BL7: =IF(BL$2=$BA7,IF(BL$2<=$BB7,parameters!$H$7,parameters!$I$7),IF(BL$2<=$BB7,parameters!$G$7,"")) -> ─ | BM7: =IF(BM$2=$BA7,IF(BM$2<=$BB7,parameters!$H$7,parameters!$I$7),IF(BM$2<=$BB7,parameters!$G$7,"")) -> ─ | BN7: =IF(BN$2=$BA7,IF(BN$2<=$BB7,parameters!$H$7,parameters!$I$7),IF(BN$2<=$BB7,parameters!$G$7,"")) -> ─ | BO7: =IF(BO$2=$BA7,IF(BO$2<=$BB7,parameters!$H$7,parameters!$I$7),IF(BO$2<=$BB7,parameters!$G$7,"")) | BP7: =IF(BP$2=$BA7,IF(BP$2<=$BB7,parameters!$H$7,parameters!$I$7),IF(BP$2<=$BB7,parameters!$G$7,"")) | BQ7: =IF(BQ$2=$BA7,IF(BQ$2<=$BB7,parameters!$H$7,parameters!$I$7),IF(BQ$2<=$BB7,parameters!$G$7,"")) | ... CB7: =IF(CB$2=$BA7,IF(CB$2<=$BB7,parameters!$H$7,parameters!$I$7),IF(CB$2<=$BB7,parameters!$G$7,""))
AT8: 44774 | AU8: 60 | AV8: 139 | AW8: 20 | AX8: =IF(AU8=0,0,AX7+AU8) -> 222 | AY8: =ROUND(AV8*parameters!$C$6,0) -> 70 | AZ8: =ROUND(AV8*parameters!$C$7,0) -> 111 | BA8: =ROUND((AW8/AV8)*20,0) -> 3 | BB8: =ROUND((AV8/AX8)*20,0) -> 13 | BC8: 20 | BD8: =ROUND((AY8/AV8)*20,0) -> 10 | BE8: =ROUND((AZ8/AV8)*20,0) -> 16 | BF8: =IF(BF$2=$BA8,IF(BF$2<=$BB8,parameters!$H$7,parameters!$I$7),IF(BF$2<=$BB8,parameters!$G$7,"")) -> ─ | BJ8: =IF(BJ$2=$BA8,IF(BJ$2<=$BB8,parameters!$H$7,parameters!$I$7),IF(BJ$2<=$BB8,parameters!$G$7,"")) -> ─ | BK8: =IF(BK$2=$BA8,IF(BK$2<=$BB8,parameters!$H$7,parameters!$I$7),IF(BK$2<=$BB8,parameters!$G$7,"")) -> ┼ | BL8: =IF(BL$2=$BA8,IF(BL$2<=$BB8,parameters!$H$7,parameters!$I$7),IF(BL$2<=$BB8,parameters!$G$7,"")) -> ─ | BM8: =IF(BM$2=$BA8,IF(BM$2<=$BB8,parameters!$H$7,parameters!$I$7),IF(BM$2<=$BB8,parameters!$G$7,"")) -> ─ | BN8: =IF(BN$2=$BA8,IF(BN$2<=$BB8,parameters!$H$7,parameters!$I$7),IF(BN$2<=$BB8,parameters!$G$7,"")) -> ─ | BO8: =IF(BO$2=$BA8,IF(BO$2<=$BB8,parameters!$H$7,parameters!$I$7),IF(BO$2<=$BB8,parameters!$G$7,"")) -> ─ | BP8: =IF(BP$2=$BA8,IF(BP$2<=$BB8,parameters!$H$7,parameters!$I$7),IF(BP$2<=$BB8,parameters!$G$7,"")) -> ─ | BQ8: =IF(BQ$2=$BA8,IF(BQ$2<=$BB8,parameters!$H$7,parameters!$I$7),IF(BQ$2<=$BB8,parameters!$G$7,"")) -> ─ | ... CB8: =IF(CB$2=$BA8,IF(CB$2<=$BB8,parameters!$H$7,parameters!$I$7),IF(CB$2<=$BB8,parameters!$G$7,""))
AT9: 44805 | AU9: 86 | AV9: 194 | AW9: 5 | AX9: =IF(AU9=0,0,AX8+AU9) -> 308 | AY9: =ROUND(AV9*parameters!$C$6,0) -> 97 | AZ9: =ROUND(AV9*parameters!$C$7,0) -> 155 | BA9: =ROUND((AW9/AV9)*20,0) -> 1 | BB9: =ROUND((AV9/AX9)*20,0) -> 13 | BC9: 20 | BD9: =ROUND((AY9/AV9)*20,0) -> 10 | BE9: =ROUND((AZ9/AV9)*20,0) -> 16 | BF9: =IF(BF$2=$BA9,IF(BF$2<=$BB9,parameters!$H$7,parameters!$I$7),IF(BF$2<=$BB9,parameters!$G$7,"")) -> ┼ | BJ9: =IF(BJ$2=$BA9,IF(BJ$2<=$BB9,parameters!$H$7,parameters!$I$7),IF(BJ$2<=$BB9,parameters!$G$7,"")) -> ─ | BK9: =IF(BK$2=$BA9,IF(BK$2<=$BB9,parameters!$H$7,parameters!$I$7),IF(BK$2<=$BB9,parameters!$G$7,"")) -> ─ | BL9: =IF(BL$2=$BA9,IF(BL$2<=$BB9,parameters!$H$7,parameters!$I$7),IF(BL$2<=$BB9,parameters!$G$7,"")) -> ─ | BM9: =IF(BM$2=$BA9,IF(BM$2<=$BB9,parameters!$H$7,parameters!$I$7),IF(BM$2<=$BB9,parameters!$G$7,"")) -> ─ | BN9: =IF(BN$2=$BA9,IF(BN$2<=$BB9,parameters!$H$7,parameters!$I$7),IF(BN$2<=$BB9,parameters!$G$7,"")) -> ─ | BO9: =IF(BO$2=$BA9,IF(BO$2<=$BB9,parameters!$H$7,parameters!$I$7),IF(BO$2<=$BB9,parameters!$G$7,"")) -> ─ | BP9: =IF(BP$2=$BA9,IF(BP$2<=$BB9,parameters!$H$7,parameters!$I$7),IF(BP$2<=$BB9,parameters!$G$7,"")) -> ─ | BQ9: =IF(BQ$2=$BA9,IF(BQ$2<=$BB9,parameters!$H$7,parameters!$I$7),IF(BQ$2<=$BB9,parameters!$G$7,"")) -> ─ | ... CB9: =IF(CB$2=$BA9,IF(CB$2<=$BB9,parameters!$H$7,parameters!$I$7),IF(CB$2<=$BB9,parameters!$G$7,""))
AT10: 44835 | AU10: 120 | AV10: 272 | AW10: 26 | AX10: =IF(AU10=0,0,AX9+AU10) -> 428 | AY10: =ROUND(AV10*parameters!$C$6,0) -> 136 | AZ10: =ROUND(AV10*parameters!$C$7,0) -> 218 | BA10: =ROUND((AW10/AV10)*20,0) -> 2 | BB10: =ROUND((AV10/AX10)*20,0) -> 13 | BC10: 20 | BD10: =ROUND((AY10/AV10)*20,0) -> 10 | BE10: =ROUND((AZ10/AV10)*20,0) -> 16 | BF10: =IF(BF$2=$BA10,IF(BF$2<=$BB10,parameters!$H$7,parameters!$I$7),IF(BF$2<=$BB10,parameters!$G$7,"")) -> ─ | BJ10: =IF(BJ$2=$BA10,IF(BJ$2<=$BB10,parameters!$H$7,parameters!$I$7),IF(BJ$2<=$BB10,parameters!$G$7,"")) -> ┼ | BK10: =IF(BK$2=$BA10,IF(BK$2<=$BB10,parameters!$H$7,parameters!$I$7),IF(BK$2<=$BB10,parameters!$G$7,"")) -> ─ | BL10: =IF(BL$2=$BA10,IF(BL$2<=$BB10,parameters!$H$7,parameters!$I$7),IF(BL$2<=$BB10,parameters!$G$7,"")) -> ─ | BM10: =IF(BM$2=$BA10,IF(BM$2<=$BB10,parameters!$H$7,parameters!$I$7),IF(BM$2<=$BB10,parameters!$G$7,"")) -> ─ | BN10: =IF(BN$2=$BA10,IF(BN$2<=$BB10,parameters!$H$7,parameters!$I$7),IF(BN$2<=$BB10,parameters!$G$7,"")) -> ─ | BO10: =IF(BO$2=$BA10,IF(BO$2<=$BB10,parameters!$H$7,parameters!$I$7),IF(BO$2<=$BB10,parameters!$G$7,"")) -> ─ | BP10: =IF(BP$2=$BA10,IF(BP$2<=$BB10,parameters!$H$7,parameters!$I$7),IF(BP$2<=$BB10,parameters!$G$7,"")) -> ─ | BQ10: =IF(BQ$2=$BA10,IF(BQ$2<=$BB10,parameters!$H$7,parameters!$I$7),IF(BQ$2<=$BB10,parameters!$G$7,"")) -> ─ | ... CB10: =IF(CB$2=$BA10,IF(CB$2<=$BB10,parameters!$H$7,parameters!$I$7),IF(CB$2<=$BB10,parameters!$G$7,""))
C11: ACT | D11: ABP | E11: LY | F11: YTD | G11: VAR | L11: Bad | T11: Good | Z11: Perfect | AT11: 44866 | AU11: 350 | AV11: 658 | AW11: 53 | AX11: =IF(AU11=0,0,AX10+AU11) -> 778 | AY11: =ROUND(AV11*parameters!$C$6,0) -> 329 | AZ11: =ROUND(AV11*parameters!$C$7,0) -> 526 | BA11: =ROUND((AW11/AV11)*20,0) -> 2 | BB11: =ROUND((AV11/AX11)*20,0) -> 17 | BC11: 20 | BD11: =ROUND((AY11/AV11)*20,0) -> 10 | BE11: =ROUND((AZ11/AV11)*20,0) -> 16 | BF11: =IF(BF$2=$BA11,IF(BF$2<=$BB11,parameters!$H$7,parameters!$I$7),IF(BF$2<=$BB11,parameters!$G$7,"")) -> ─ | BJ11: =IF(BJ$2=$BA11,IF(BJ$2<=$BB11,parameters!$H$7,parameters!$I$7),IF(BJ$2<=$BB11,parameters!$G$7,"")) -> ┼ | BK11: =IF(BK$2=$BA11,IF(BK$2<=$BB11,parameters!$H$7,parameters!$I$7),IF(BK$2<=$BB11,parameters!$G$7,"")) -> ─ | BL11: =IF(BL$2=$BA11,IF(BL$2<=$BB11,parameters!$H$7,parameters!$I$7),IF(BL$2<=$BB11,parameters!$G$7,"")) -> ─ | BM11: =IF(BM$2=$BA11,IF(BM$2<=$BB11,parameters!$H$7,parameters!$I$7),IF(BM$2<=$BB11,parameters!$G$7,"")) -> ─ | BN11: =IF(BN$2=$BA11,IF(BN$2<=$BB11,parameters!$H$7,parameters!$I$7),IF(BN$2<=$BB11,parameters!$G$7,"")) -> ─ | BO11: =IF(BO$2=$BA11,IF(BO$2<=$BB11,parameters!$H$7,parameters!$I$7),IF(BO$2<=$BB11,parameters!$G$7,"")) -> ─ | BP11: =IF(BP$2=$BA11,IF(BP$2<=$BB11,parameters!$H$7,parameters!$I$7),IF(BP$2<=$BB11,parameters!$G$7,"")) -> ─ | BQ11: =IF(BQ$2=$BA11,IF(BQ$2<=$BB11,parameters!$H$7,parameters!$I$7),IF(BQ$2<=$BB11,parameters!$G$7,"")) -> ─ | ... CB11: =IF(CB$2=$BA11,IF(CB$2<=$BB11,parameters!$H$7,parameters!$I$7),IF(CB$2<=$BB11,parameters!$G$7,""))
B12: RN | C12: =AU18 -> 37 | D12: =AV18 -> 50 | E12: =AW18 -> 29 | F12: =AX18 -> 62 | G12: =(C12-D12)/D12 -> -0.26 | I12: =IF(BF$2=$BA18,IF(BF$2<=$BB18,parameters!$H$7,parameters!$I$7),IF(BF$2<=$BB18,parameters!$G$7,"")) -> ─ | J12: =IF(BJ$2=$BA18,IF(BJ$2<=$BB18,parameters!$H$7,parameters!$I$7),IF(BJ$2<=$BB18,parameters!$G$7,"")) -> ─ | K12: =IF(BK$2=$BA18,IF(BK$2<=$BB18,parameters!$H$7,parameters!$I$7),IF(BK$2<=$BB18,parameters!$G$7,"")) -> ─ | L12: =IF(BL$2=$BA18,IF(BL$2<=$BB18,parameters!$H$7,parameters!$I$7),IF(BL$2<=$BB18,parameters!$G$7,"")) -> ─ | M12: =IF(BM$2=$BA18,IF(BM$2<=$BB18,parameters!$H$7,parameters!$I$7),IF(BM$2<=$BB18,parameters!$G$7,"")) -> ─ | N12: =IF(BN$2=$BA18,IF(BN$2<=$BB18,parameters!$H$7,parameters!$I$7),IF(BN$2<=$BB18,parameters!$G$7,"")) -> ─ | O12: =IF(BO$2=$BA18,IF(BO$2<=$BB18,parameters!$H$7,parameters!$I$7),IF(BO$2<=$BB18,parameters!$G$7,"")) -> ─ | P12: =IF(BP$2=$BA18,IF(BP$2<=$BB18,parameters!$H$7,parameters!$I$7),IF(BP$2<=$BB18,parameters!$G$7,"")) -> ─ | Q12: =IF(BQ$2=$BA18,IF(BQ$2<=$BB18,parameters!$H$7,parameters!$I$7),IF(BQ$2<=$BB18,parameters!$G$7,"")) -> ─ | ... AA12: =IF(CA$2=$BA18,IF(CA$2<=$BB18,parameters!$H$7,parameters!$I$7),IF(CA$2<=$BB18,parameters!$G$7,"")) | AT12: 44896 | AU12: 900 | AV12: 704 | AW12: 26 | AX12: =IF(AU12=0,0,AX11+AU12) -> 1678 | AY12: =ROUND(AV12*parameters!$C$6,0) -> 352 | AZ12: =ROUND(AV12*parameters!$C$7,0) -> 563 | BA12: =ROUND((AW12/AV12)*20,0) -> 1 | BB12: =ROUND((AV12/AX12)*20,0) -> 8 | BC12: 20 | BD12: =ROUND((AY12/AV12)*20,0) -> 10 | BE12: =ROUND((AZ12/AV12)*20,0) -> 16 | BF12: =IF(BF$2=$BA12,IF(BF$2<=$BB12,parameters!$H$7,parameters!$I$7),IF(BF$2<=$BB12,parameters!$G$7,"")) -> ┼ | BJ12: =IF(BJ$2=$BA12,IF(BJ$2<=$BB12,parameters!$H$7,parameters!$I$7),IF(BJ$2<=$BB12,parameters!$G$7,"")) -> ─ | BK12: =IF(BK$2=$BA12,IF(BK$2<=$BB12,parameters!$H$7,parameters!$I$7),IF(BK$2<=$BB12,parameters!$G$7,"")) -> ─ | BL12: =IF(BL$2=$BA12,IF(BL$2<=$BB12,parameters!$H$7,parameters!$I$7),IF(BL$2<=$BB12,parameters!$G$7,"")) -> ─ | BM12: =IF(BM$2=$BA12,IF(BM$2<=$BB12,parameters!$H$7,parameters!$I$7),IF(BM$2<=$BB12,parameters!$G$7,"")) -> ─ | BN12: =IF(BN$2=$BA12,IF(BN$2<=$BB12,parameters!$H$7,parameters!$I$7),IF(BN$2<=$BB12,parameters!$G$7,"")) -> ─ | BO12: =IF(BO$2=$BA12,IF(BO$2<=$BB12,parameters!$H$7,parameters!$I$7),IF(BO$2<=$BB12,parameters!$G$7,"")) -> ─ | BP12: =IF(BP$2=$BA12,IF(BP$2<=$BB12,parameters!$H$7,parameters!$I$7),IF(BP$2<=$BB12,parameters!$G$7,"")) -> ─ | BQ12: =IF(BQ$2=$BA12,IF(BQ$2<=$BB12,parameters!$H$7,parameters!$I$7),IF(BQ$2<=$BB12,parameters!$G$7,"")) | ... CB12: =IF(CB$2=$BA12,IF(CB$2<=$BB12,parameters!$H$7,parameters!$I$7),IF(CB$2<=$BB12,parameters!$G$7,""))
AT13: 44927 | AU13: 790 | AV13: 684 | AW13: 27 | AX13: =IF(AU13=0,0,AX12+AU13) -> 2468 | AY13: =ROUND(AV13*parameters!$C$6,0) -> 342 | AZ13: =ROUND(AV13*parameters!$C$7,0) -> 547 | BA13: =ROUND((AW13/AV13)*20,0) -> 1 | BB13: =ROUND((AV13/AX13)*20,0) -> 6 | BC13: 20 | BD13: =ROUND((AY13/AV13)*20,0) -> 10 | BE13: =ROUND((AZ13/AV13)*20,0) -> 16 | BF13: =IF(BF$2=$BA13,IF(BF$2<=$BB13,parameters!$H$7,parameters!$I$7),IF(BF$2<=$BB13,parameters!$G$7,"")) -> ┼ | BJ13: =IF(BJ$2=$BA13,IF(BJ$2<=$BB13,parameters!$H$7,parameters!$I$7),IF(BJ$2<=$BB13,parameters!$G$7,"")) -> ─ | BK13: =IF(BK$2=$BA13,IF(BK$2<=$BB13,parameters!$H$7,parameters!$I$7),IF(BK$2<=$BB13,parameters!$G$7,"")) -> ─ | BL13: =IF(BL$2=$BA13,IF(BL$2<=$BB13,parameters!$H$7,parameters!$I$7),IF(BL$2<=$BB13,parameters!$G$7,"")) -> ─ | BM13: =IF(BM$2=$BA13,IF(BM$2<=$BB13,parameters!$H$7,parameters!$I$7),IF(BM$2<=$BB13,parameters!$G$7,"")) -> ─ | BN13: =IF(BN$2=$BA13,IF(BN$2<=$BB13,parameters!$H$7,parameters!$I$7),IF(BN$2<=$BB13,parameters!$G$7,"")) -> ─ | BO13: =IF(BO$2=$BA13,IF(BO$2<=$BB13,parameters!$H$7,parameters!$I$7),IF(BO$2<=$BB13,parameters!$G$7,"")) | BP13: =IF(BP$2=$BA13,IF(BP$2<=$BB13,parameters!$H$7,parameters!$I$7),IF(BP$2<=$BB13,parameters!$G$7,"")) | BQ13: =IF(BQ$2=$BA13,IF(BQ$2<=$BB13,parameters!$H$7,parameters!$I$7),IF(BQ$2<=$BB13,parameters!$G$7,"")) | ... CB13: =IF(CB$2=$BA13,IF(CB$2<=$BB13,parameters!$H$7,parameters!$I$7),IF(CB$2<=$BB13,parameters!$G$7,""))
B14: Sales Trend | AT14: 44958 | AU14: 678 | AV14: 931 | AW14: 19 | AX14: =IF(AU14=0,0,AX13+AU14) -> 3146 | AY14: =ROUND(AV14*parameters!$C$6,0) -> 466 | AZ14: =ROUND(AV14*parameters!$C$7,0) -> 745 | BA14: =ROUND((AW14/AV14)*20,0) -> 0 | BB14: =ROUND((AV14/AX14)*20,0) -> 6 | BC14: 20 | BD14: =ROUND((AY14/AV14)*20,0) -> 10 | BE14: =ROUND((AZ14/AV14)*20,0) -> 16 | BF14: =IF(BF$2=$BA14,IF(BF$2<=$BB14,parameters!$H$7,parameters!$I$7),IF(BF$2<=$BB14,parameters!$G$7,"")) -> ─ | BJ14: =IF(BJ$2=$BA14,IF(BJ$2<=$BB14,parameters!$H$7,parameters!$I$7),IF(BJ$2<=$BB14,parameters!$G$7,"")) -> ─ | BK14: =IF(BK$2=$BA14,IF(BK$2<=$BB14,parameters!$H$7,parameters!$I$7),IF(BK$2<=$BB14,parameters!$G$7,"")) -> ─ | BL14: =IF(BL$2=$BA14,IF(BL$2<=$BB14,parameters!$H$7,parameters!$I$7),IF(BL$2<=$BB14,parameters!$G$7,"")) -> ─ | BM14: =IF(BM$2=$BA14,IF(BM$2<=$BB14,parameters!$H$7,parameters!$I$7),IF(BM$2<=$BB14,parameters!$G$7,"")) -> ─ | BN14: =IF(BN$2=$BA14,IF(BN$2<=$BB14,parameters!$H$7,parameters!$I$7),IF(BN$2<=$BB14,parameters!$G$7,"")) -> ─ | BO14: =IF(BO$2=$BA14,IF(BO$2<=$BB14,parameters!$H$7,parameters!$I$7),IF(BO$2<=$BB14,parameters!$G$7,"")) | BP14: =IF(BP$2=$BA14,IF(BP$2<=$BB14,parameters!$H$7,parameters!$I$7),IF(BP$2<=$BB14,parameters!$G$7,"")) | BQ14: =IF(BQ$2=$BA14,IF(BQ$2<=$BB14,parameters!$H$7,parameters!$I$7),IF(BQ$2<=$BB14,parameters!$G$7,"")) | ... CB14: =IF(CB$2=$BA14,IF(CB$2<=$BB14,parameters!$H$7,parameters!$I$7),IF(CB$2<=$BB14,parameters!$G$7,""))
AT15: 44986 | AU15: 900 | AV15: 1081 | AW15: 30 | AX15: =IF(AU15=0,0,AX14+AU15) -> 4046 | AY15: =ROUND(AV15*parameters!$C$6,0) -> 541 | AZ15: =ROUND(AV15*parameters!$C$7,0) -> 865 | BA15: =ROUND((AW15/AV15)*20,0) -> 1 | BB15: =ROUND((AV15/AX15)*20,0) -> 5 | BC15: 20 | BD15: =ROUND((AY15/AV15)*20,0) -> 10 | BE15: =ROUND((AZ15/AV15)*20,0) -> 16 | BF15: =IF(BF$2=$BA15,IF(BF$2<=$BB15,parameters!$H$7,parameters!$I$7),IF(BF$2<=$BB15,parameters!$G$7,"")) -> ┼ | BJ15: =IF(BJ$2=$BA15,IF(BJ$2<=$BB15,parameters!$H$7,parameters!$I$7),IF(BJ$2<=$BB15,parameters!$G$7,"")) -> ─ | BK15: =IF(BK$2=$BA15,IF(BK$2<=$BB15,parameters!$H$7,parameters!$I$7),IF(BK$2<=$BB15,parameters!$G$7,"")) -> ─ | BL15: =IF(BL$2=$BA15,IF(BL$2<=$BB15,parameters!$H$7,parameters!$I$7),IF(BL$2<=$BB15,parameters!$G$7,"")) -> ─ | BM15: =IF(BM$2=$BA15,IF(BM$2<=$BB15,parameters!$H$7,parameters!$I$7),IF(BM$2<=$BB15,parameters!$G$7,"")) -> ─ | BN15: =IF(BN$2=$BA15,IF(BN$2<=$BB15,parameters!$H$7,parameters!$I$7),IF(BN$2<=$BB15,parameters!$G$7,"")) | BO15: =IF(BO$2=$BA15,IF(BO$2<=$BB15,parameters!$H$7,parameters!$I$7),IF(BO$2<=$BB15,parameters!$G$7,"")) | BP15: =IF(BP$2=$BA15,IF(BP$2<=$BB15,parameters!$H$7,parameters!$I$7),IF(BP$2<=$BB15,parameters!$G$7,"")) | BQ15: =IF(BQ$2=$BA15,IF(BQ$2<=$BB15,parameters!$H$7,parameters!$I$7),IF(BQ$2<=$BB15,parameters!$G$7,"")) | ... CB15: =IF(CB$2=$BA15,IF(CB$2<=$BB15,parameters!$H$7,parameters!$I$7),IF(CB$2<=$BB15,parameters!$G$7,""))
AU16: =SUM(AU4:AU15) -> 4046
AT17: 2 | AU17: Actual | AV17: Budgeted | AW17: Last Year | AX17: YTD | AY17: Bad | AZ17: Ok | BA17: Last Year | BB17: RN | BC17: Total | BD17: Bad | BE17: Ok
AT18: =INDEX(RN,$AT$17+1,1) -> 44682 | AU18: =INDEX(RN,$AT$17+1,2) -> 37 | AV18: =INDEX(RN,$AT$17+1,3) -> 50 | AW18: =INDEX(RN,$AT$17+1,4) -> 29 | AX18: =INDEX(RN,$AT$17+1,5) -> 62 | AY18: =INDEX(RN,$AT$17+1,6) -> 25 | AZ18: =INDEX(RN,$AT$17+1,7) -> 40 | BA18: =INDEX(RN,$AT$17+1,8) -> 12 | BB18: =INDEX(RN,$AT$17+1,9) -> 15 | BC18: =INDEX(RN,$AT$17+1,10) -> 20 | BD18: =INDEX(RN,$AT$17+1,11) -> 10 | BE18: =INDEX(RN,$AT$17+1,12) -> 16
B20: Momentum | C20: =C12/DAY(TODAY()) -> 1.85 | D20: Room Nights Per Day | AT20: A&P Spend | BB20: ▼
C21: =INDEX(RN,$AT$17-1,1) -> RN | D21: =INDEX(RN,$AT$17,1) -> 44652 | E21: =INDEX(RN,$AT$17+1,1) -> 44682 | AU21: Total
C22: =INDEX(RN,$AT$17-1,2)/30 -> #VALUE! | D22: =INDEX(RN,$AT$17,2)/30 -> 0.83333333 | E22: =INDEX(RN,$AT$17+1,2)/30 -> 1.2333333 | AU22: Online | AZ22: Offline
AU23: Google | AV23: Yahoo | AW23: FB | AX23: Others | AY23: Total | AZ23: Newspaper | BA23: Fair | BB23: Others | BC23: Total | BD23: Grand Total
B24: Destination Effectiveness | AT24: 40269 | AU24: 3661 | AV24: 200 | AX24: 200 | AY24: =SUM(AU24:AX24) -> 4061 | BC24: =SUM(AZ24:BB24) -> 0 | BD24: =BC24+AY24 -> 4061
C25: A&P Cost | D25: RN | E25: Cost/RN | F25: % | AT25: 40299 | AU25: 4928 | AV25: 120 | AX25: 200 | AY25: =SUM(AU25:AX25) -> 5248 | BC25: =SUM(AZ25:BB25) -> 0 | BD25: =BC25+AY25 -> 5248
B26: Sort By | C26: 1 | D26: 2 | E26: 3 | F26: 4 | AT26: 40330 | AU26: 2636 | AV26: 300 | AW26: 372 | AX26: 200 | AY26: =SUM(AU26:AX26) -> 3508 | AZ26: 1000 | BC26: =SUM(AZ26:BB26) -> 1000 | BD26: =BC26+AY26 -> 4508
B27: Sort Order | C27: =IF(mySortCriteria=C26,CHOOSE($AU$118,"▼","▲"),"") | D27: =IF(mySortCriteria=D26,CHOOSE($AU$118,"▼","▲"),"") -> ▲ | E27: =IF(mySortCriteria=E26,CHOOSE($AU$118,"▼","▲"),"") | F27: =IF(mySortCriteria=F26,CHOOSE($AU$118,"▼","▲"),"") | AT27: 40360 | AU27: 1809 | AV27: 200 | AW27: 234 | AX27: 240 | AY27: =SUM(AU27:AX27) -> 2483 | AZ27: 1000 | BC27: =SUM(AZ27:BB27) -> 1000 | BD27: =BC27+AY27 -> 3483
B28: =OFFSET($AZ119,1,0) -> AUSTRALIA | C28: =OFFSET($AZ119,1,1) -> 0 | D28: =OFFSET($AZ119,1,2) -> 0 | E28: =OFFSET($AZ119,1,3) -> 0 | F28: =OFFSET($AZ119,1,4) -> 0 | AT28: 40391 | AU28: 2500 | AV28: 300 | AW28: 1300 | AX28: 300 | AY28: =SUM(AU28:AX28) -> 4400 | BC28: =SUM(AZ28:BB28) -> 0 | BD28: =BC28+AY28 -> 4400
B29: =OFFSET($AZ120,1,0) -> JAPAN | C29: =OFFSET($AZ120,1,1) -> 194.592 | D29: =OFFSET($AZ120,1,2) -> 0 | E29: =OFFSET($AZ120,1,3) -> 0 | F29: =OFFSET($AZ120,1,4) -> 0 | AT29: 40422 | AU29: 2700 | AV29: 500 | AW29: 1500 | AX29: 300 | AY29: =SUM(AU29:AX29) -> 5000 | BC29: =SUM(AZ29:BB29) -> 0 | BD29: =BC29+AY29 -> 5000
B30: =OFFSET($AZ121,1,0) -> PHILLIPINES | C30: =OFFSET($AZ121,1,1) -> 0 | D30: =OFFSET($AZ121,1,2) -> 0 | E30: =OFFSET($AZ121,1,3) -> 0 | F30: =OFFSET($AZ121,1,4) -> 0 | AT30: 40452 | AU30: 3000 | AV30: 450 | AW30: 1600 | AX30: 300 | AY30: =SUM(AU30:AX30) -> 5350 | BC30: =SUM(AZ30:BB30) -> 0 | BD30: =BC30+AY30 -> 5350
B31: =OFFSET($AZ122,1,0) -> TAIWAN | C31: =OFFSET($AZ122,1,1) -> 24.704 | D31: =OFFSET($AZ122,1,2) -> 0 | E31: =OFFSET($AZ122,1,3) -> 0 | F31: =OFFSET($AZ122,1,4) -> 0 | AT31: 40483 | AU31: 3400 | AV31: 500 | AW31: 1650 | AX31: 300 | AY31: =SUM(AU31:AX31) -> 5850 | AZ31: 3000 | BC31: =SUM(AZ31:BB31) -> 3000 | BD31: =BC31+AY31 -> 8850
B32: =OFFSET($AZ123,1,0) -> THAILAND | C32: =OFFSET($AZ123,1,1) -> 413.792 | D32: =OFFSET($AZ123,1,2) -> 0 | E32: =OFFSET($AZ123,1,3) -> 0 | F32: =OFFSET($AZ123,1,4) -> 0 | AT32: 40513 | AU32: 3000 | AV32: 600 | AW32: 1700 | AX32: 300 | AY32: =SUM(AU32:AX32) -> 5600 | BA32: 15000 | BC32: =SUM(AZ32:BB32) -> 15000 | BD32: =BC32+AY32 -> 20600
B33: =OFFSET($AZ124,1,0) -> VIETNAM | C33: =OFFSET($AZ124,1,1) -> 672.32 | D33: =OFFSET($AZ124,1,2) -> 0 | E33: =OFFSET($AZ124,1,3) -> 0 | F33: =OFFSET($AZ124,1,4) -> 0 | AT33: 40544 | AU33: 3500 | AV33: 470 | AW33: 1750 | AX33: 300 | AY33: =SUM(AU33:AX33) -> 6020 | BC33: =SUM(AZ33:BB33) -> 0 | BD33: =BC33+AY33 -> 6020
B34: =OFFSET($AZ125,1,0) -> MALAYSIA_FB | C34: =OFFSET($AZ125,1,1) -> 0 | D34: =OFFSET($AZ125,1,2) -> 0 | E34: =OFFSET($AZ125,1,3) -> 0 | F34: =OFFSET($AZ125,1,4) -> 0 | AT34: 40575 | AU34: 4000 | AV34: 560 | AW34: 1800 | AX34: 300 | AY34: =SUM(AU34:AX34) -> 6660 | BC34: =SUM(AZ34:BB34) -> 0 | BD34: =BC34+AY34 -> 6660
B35: =OFFSET($AZ126,1,0) -> SINGAPORE_FB | C35: =OFFSET($AZ126,1,1) -> 0 | D35: =OFFSET($AZ126,1,2) -> 0 | E35: =OFFSET($AZ126,1,3) -> 0 | F35: =OFFSET($AZ126,1,4) -> 0 | AT35: 40603 | AU35: 4300 | AV35: 600 | AW35: 1900 | AX35: 300 | AY35: =SUM(AU35:AX35) -> 7100 | BC35: =SUM(AZ35:BB35) -> 0 | BD35: =BC35+AY35 -> 7100
B36: =OFFSET($AZ127,1,0) -> MACAU | C36: =OFFSET($AZ127,1,1) -> 206.528 | D36: =OFFSET($AZ127,1,2) -> 2 | E36: =OFFSET($AZ127,1,3) -> 103.264 | F36: =OFFSET($AZ127,1,4) -> 0.39716923 | AU36: =SUM(AU24:AU35) -> 39434 | AV36: =SUM(AV24:AV35) -> 4800 | AW36: =SUM(AW24:AW35) -> 13806 | AX36: =SUM(AX24:AX35) -> 3240 | AY36: =SUM(AY24:AY35) -> 61280 | AZ36: =SUM(AZ24:AZ35) -> 5000 | BA36: =SUM(BA24:BA35) -> 15000 | BB36: =SUM(BB24:BB35) -> 0 | BC36: =SUM(BC24:BC35) -> 20000 | BD36: =BC36+AY36 -> 81280
B37: =OFFSET($AZ128,1,0) -> CHINA | C37: =OFFSET($AZ128,1,1) -> 195.008 | D37: =OFFSET($AZ128,1,2) -> 3 | E37: =OFFSET($AZ128,1,3) -> 65.002667 | F37: =OFFSET($AZ128,1,4) -> 0.25001026
B38: =OFFSET($AZ129,1,0) -> INDONESIA | C38: =OFFSET($AZ129,1,1) -> 740.64 | D38: =OFFSET($AZ129,1,2) -> 4 | E38: =OFFSET($AZ129,1,3) -> 185.16 | F38: =OFFSET($AZ129,1,4) -> 0.71215385 | AT38: To show pie
B39: =OFFSET($AZ130,1,0) -> HONG KONG | C39: =OFFSET($AZ130,1,1) -> 211.072 | D39: =OFFSET($AZ130,1,2) -> 6 | E39: =OFFSET($AZ130,1,3) -> 35.178667 | F39: =OFFSET($AZ130,1,4) -> 0.13530256 | AU39: Google | AV39: Yahoo | AW39: FB | AX39: Online Oths | AY39: Newspaper | AZ39: Fair | BA39: Offline Oths
B40: =OFFSET($AZ131,1,0) -> MALAYSIA | C40: =OFFSET($AZ131,1,1) -> 597.824 | D40: =OFFSET($AZ131,1,2) -> 11 | E40: =OFFSET($AZ131,1,3) -> 54.347636 | F40: =OFFSET($AZ131,1,4) -> 0.20902937 | AT40: =INDEX(AP,$AT$17+1,1) -> 40299 | AU40: =INDEX(AP,$AT$17+1,2) -> 4928 | AV40: =INDEX(AP,$AT$17+1,3) -> 120 | AW40: =INDEX(AP,$AT$17+1,4) -> 0 | AX40: =INDEX(AP,$AT$17+1,5) -> 200 | AY40: =INDEX(AP,$AT$17+1,7) -> 0 | AZ40: =INDEX(AP,$AT$17+1,8) -> 0 | BA40: =INDEX(AP,$AT$17+1,9) -> 0
B41: =OFFSET($AZ132,1,0) -> SINGAPORE | C41: =OFFSET($AZ132,1,1) -> 1671.36 | D41: =OFFSET($AZ132,1,2) -> 11 | E41: =OFFSET($AZ132,1,3) -> 151.94182 | F41: =OFFSET($AZ132,1,4) -> 0.58439161
B42: Note:
...

Sheet parameters
B2: Site : | C2: Sample Travel Site | G2: Data Table
B3: Month : | G3: 1. Daily A&P spend table including Google, Yahoo, FB, Ads, others BY Destination
B4: Avg Rate | C4: 260 | G4: 2. Daily RN by Destination
G5: 3. Daily Traffics
B6: Bad | C6: 0.5
B7: Ok | C7: 0.8 | G7: ─ | H7: ┼ | I7: ▐ | J7: ▐
B9: Cost/RN Benchmark | C9: 10 | D9: If the Cost per room night is higher this number, the city is highlighted
B11: AUSTRALIA
B12: CHINA
B13: HONG KONG
B14: INDONESIA
B15: JAPAN
B16: MACAU
B17: MALAYSIA
B18: PHILLIPINES
B19: SINGAPORE
B20: TAIWAN
B21: THAILAND
B22: VIETNAM
